Workbook

Sheet BABY Présence
C1: BABY SOCCER
C4: MAJ LISTE 11/03 : 12h15 | E4: 45910 | F4: =E4+7 -> 45917 | G4: =F4+7 -> 45924 | H4: =G4+7 -> 45931 | I4: =H4+7 -> 45938 | J4: =I4+7 -> 45945 | K4: =J4+7 -> 45952 | L4: =K4+7 -> 45959 | M4: =L4+7 -> 45966 | ... AT4: =AS4+7 -> 46197
C5: TOTAL INSCRIPTION EDF : | D5: =C62+'LUNDI 17H30 Présence'!C45+'MARDI 17H30 Présence'!C45+'MERCREDI 14h Présence'!C65+'MERCREDI 15h45 Présence '!C65+'VENDREDI 17h30 Présence'!C65+'SAMEDI 9h30 Présence'!C85+'SAMEDI 11h15 Présence'!C85+'SAMEDI 14h00 Présence'!C45+'SAMEDI 15h45 Présence'!C45 -> 321
A6: MERCREDI 14h30 | B6: MERCREDI 14h30 | E6: S1 | F6: S2 | G6: S3 | H6: S4 | I6: S5 | J6: S6 | K6: V | L6: V | M6: S7 | N6: S8 | O6: S9 | P6: S10 | Q6: S11 | R6: S12 | S6: S13 | T6: V | U6: V | V6: S14 | W6: S15 | X6: S16 | Y6: S17 | Z6: S18 | AA6: S19 | AB6: S20 | AC6: V | AD6: V | AE6: S21 | AF6: S22 | AG6: S23 | AH6: S24 | AI6: S25 | AJ6: S26 | AK6: V | AL6: V | AM6: S27 | AN6: S28 | AO6: F | AP6: S29 | AQ6: S30 | AR6: S31 | AS6: S32 | AT6: S33
B7: 1 | C7: AMARA Aylan | D7: U5 | E7: 1 | F7: 0 | G7: 1 | H7: 1 | I7: 1 | J7: 1 | M7: 1 | N7: 1 | O7: 1 | P7: 1 | Q7: 1 | R7: 1 | S7: 1 | V7: 0 | W7: 1 | X7: 0 | Y7: 0 | Z7: 1 | AA7: 1 | AB7: 1 | AD7: 1 | AE7: 1 | AF7: 1 | AG7: 0 | AU7: =SUM(E7:AT7) -> 19
B8: 2 | C8: MANGA Farell | D8: U5 | E8: 1 | F8: 1 | G8: 1 | H8: 1 | I8: 0 | J8: 1 | M8: 1 | N8: 1 | O8: 1 | P8: 1 | Q8: 1 | R8: 0 | S8: 1 | V8: 1 | W8: 1 | X8: 1 | Y8: 1 | Z8: 0 | AA8: 1 | AB8: 1 | AD8: 0 | AE8: 1 | AF8: 1 | AG8: 1 | AU8: =SUM(E8:AT8) -> 20
B9: 3 | C9: DIABY Ibrahima | D9: U5 | E9: 1 | F9: 1 | G9: 1 | H9: 1 | I9: 1 | J9: 1 | M9: 1 | N9: 1 | O9: 0 | P9: 1 | Q9: 1 | R9: 1 | S9: 0 | V9: 1 | W9: 0 | X9: 0 | Y9: 1 | Z9: 1 | AA9: 1 | AB9: 1 | AD9: 1 | AE9: 1 | AF9: 1 | AG9: 1 | AU9: =SUM(E9:AT9) -> 20
B10: 4 | C10: SONGABIMA NDOMBASI Braxton | D10: U5 | E10: 0 | F10: 1 | G10: 1 | H10: 1 | I10: 1 | J10: 1 | M10: 1 | N10: 1 | O10: 1 | P10: 1 | Q10: 1 | R10: 1 | S10: 1 | V10: 1 | W10: 1 | X10: 1 | Y10: 1 | Z10: 1 | AA10: 1 | AB10: 1 | AD10: 0 | AE10: 1 | AF10: 1 | AG10: 1 | AU10: =SUM(E10:AT10) -> 22
B11: 5 | C11: RAHMAOUI Ilyan | D11: U5 | E11: 1 | F11: 0 | G11: 1 | H11: 0 | I11: 0 | J11: 0 | M11: 1 | N11: 1 | O11: 1 | P11: 1 | Q11: 1 | R11: 0 | S11: 1 | V11: 1 | W11: 1 | X11: 1 | Y11: 1 | Z11: 1 | AA11: 1 | AB11: 1 | AD11: 0 | AE11: 1 | AF11: 1 | AG11: 1 | AU11: =SUM(E11:AT11) -> 18
B12: 6 | C12: BENNABI Issam | D12: U5 | E12: 0 | F12: 0 | G12: 0 | H12: 0 | I12: 0 | J12: 0 | M12: 0 | N12: 0 | O12: 0 | P12: 1 | Q12: 1 | R12: 1 | S12: 1 | V12: 1 | W12: 1 | X12: 1 | Y12: 1 | Z12: 1 | AA12: 1 | AB12: 0 | AE12: 0 | AF12: 0 | AG12: 1 | AU12: =SUM(E12:AT12) -> 11
B13: 7 | C13: ALTINSOY Kenan | D13: U5 | E13: 0 | F13: 0 | G13: 0 | H13: 0 | I13: 0 | J13: 0 | M13: 0 | N13: 1 | O13: 1 | P13: 0 | Q13: 0 | R13: 0 | S13: 0 | V13: 0 | W13: 0 | X13: 1 | Y13: 0 | Z13: 0 | AA13: 0 | AB13: 0 | AE13: 0 | AF13: 0 | AG13: 0 | AU13: =SUM(E13:AT13) -> 3
B14: 8 | C14: CALOIN Enzo | D14: U5 | E14: 0 | F14: 0 | G14: 0 | H14: 0 | I14: 0 | J14: 0 | M14: 0 | N14: 0 | O14: 0 | P14: 0 | Q14: 0 | R14: 0 | S14: 0 | V14: 0 | W14: 0 | X14: 0 | Y14: 1 | Z14: 1 | AA14: 1 | AB14: 1 | AE14: 1 | AF14: 1 | AG14: 1 | AU14: =SUM(E14:AT14) -> 7
B15: 9 | AU15: =SUM(E15:AT15) -> 0
B16: 10 | AU16: =SUM(E16:AT16) -> 0
B17: 8 | C17: TOTAL G1 | E17: =SUM(E7:E16) -> 4 | F17: =SUM(F7:F16) -> 3 | G17: =SUM(G7:G16) -> 5 | H17: =SUM(H7:H16) -> 4 | I17: =SUM(I7:I16) -> 3 | J17: =SUM(J7:J16) -> 4 | K17: =SUM(K7:K16) -> 0 | L17: =SUM(L7:L16) -> 0 | ... AT17: =SUM(AT7:AT16) -> 0
A19: MERCREDI 17h30 | B19: MERCREDI 17h30 | E19: S1 | F19: S2 | G19: S3 | H19: S4 | I19: S5 | J19: S6 | K19: V | L19: V | M19: S7 | N19: S8 | O19: S9 | P19: S10 | Q19: S11 | R19: S12 | S19: S13 | T19: V | U19: V | V19: S14 | W19: S15 | X19: S16 | Y19: S17 | Z19: S18 | AA19: S19 | AB19: S20 | AC19: V | AD19: V | AE19: S21 | AF19: S22 | AG19: S23 | AH19: S24 | AI19: S25 | AJ19: S26 | AK19: V | AL19: V | AM19: S27 | AN19: S28 | AO19: F | AP19: S29 | AQ19: S30 | AR19: S31 | AS19: S32 | AT19: S33
B20: 1 | C20: PILLAS Matéo | D20: U5 | E20: 1 | F20: 1 | G20: 1 | H20: 1 | I20: 1 | J20: 1 | M20: 1 | N20: 0 | O20: 1 | P20: 1 | Q20: 0 | R20: 1 | V20: 0 | W20: 1 | X20: 1 | Y20: 1 | Z20: 1 | AA20: 1 | AB20: 0 | AE20: 1 | AF20: 1 | AG20: 1 | AU20: =SUM(E20:AT20) -> 18
B21: 2 | C21: BARGACH Adam | D21: U5 | E21: 1 | F21: 1 | G21: 1 | H21: 1 | I21: 1 | J21: 1 | M21: 1 | N21: 1 | O21: 1 | P21: 1 | Q21: 1 | R21: 1 | V21: 1 | W21: 1 | X21: 1 | Y21: 1 | Z21: 1 | AA21: 1 | AB21: 1 | AE21: 1 | AF21: 1 | AG21: 1 | AU21: =SUM(E21:AT21) -> 22
B22: 3 | C22: ALMEIDA SOAVE Elikiah | D22: U5 | E22: 1 | F22: 1 | G22: 1 | H22: 1 | I22: 1 | J22: 1 | M22: 1 | N22: 1 | O22: 1 | P22: 1 | Q22: 1 | R22: 1 | V22: 1 | W22: 1 | X22: 1 | Y22: 0 | Z22: 1 | AA22: 1 | AB22: 1 | AE22: 1 | AF22: 1 | AG22: 1 | AU22: =SUM(E22:AT22) -> 21
B23: 4 | C23: MARTIN TROYES Nathan | D23: U5 | E23: 0 | F23: 1 | G23: 1 | H23: 1 | I23: 1 | J23: 1 | M23: 1 | N23: 1 | O23: 1 | P23: 1 | Q23: 0 | R23: 1 | V23: 1 | W23: 1 | X23: 1 | Y23: 0 | Z23: 1 | AA23: 1 | AB23: 1 | AE23: 1 | AF23: 0 | AG23: 1 | AU23: =SUM(E23:AT23) -> 18
B24: 5 | C24: SIMON Taïryk | D24: U5 | E24: 1 | F24: 1 | G24: 1 | H24: 1 | I24: 1 | J24: 1 | M24: 1 | N24: 0 | O24: 1 | P24: 1 | Q24: 1 | R24: 1 | V24: 1 | W24: 1 | X24: 1 | Y24: 1 | Z24: 0 | AA24: 1 | AB24: 1 | AE24: 1 | AF24: 1 | AG24: 1 | AU24: =SUM(E24:AT24) -> 20
B25: 6 | C25: JAMALEDDINE Nail | D25: U5 | E25: 1 | F25: 1 | G25: 0 | H25: 1 | I25: 1 | J25: 1 | M25: 1 | N25: 1 | O25: 0 | P25: 0 | Q25: 1 | R25: 0 | V25: 0 | W25: 1 | X25: 0 | Y25: 0 | Z25: 0 | AA25: 0 | AB25: 0 | AE25: 0 | AF25: 0 | AG25: 0 | AU25: =SUM(E25:AT25) -> 9
B26: 7 | C26: NGUEMA MEDANG Alpha | D26: U5 | E26: 1 | F26: 1 | G26: 0 | H26: 1 | I26: 1 | J26: 0 | M26: 1 | N26: 1 | O26: 1 | P26: 0 | Q26: 1 | R26: 1 | V26: 1 | W26: 0 | X26: 0 | Y26: 0 | Z26: 0 | AA26: 1 | AB26: 0 | AE26: 0 | AF26: 0 | AG26: 0 | AU26: =SUM(E26:AT26) -> 11
B27: 8 | C27: BENZITOUNI Noham | D27: U5 | E27: 0 | F27: 1 | G27: 1 | H27: 1 | I27: 1 | J27: 1 | M27: 0 | N27: 1 | O27: 1 | P27: 1 | Q27: 1 | R27: 1 | V27: 1 | W27: 1 | X27: 1 | Y27: 1 | Z27: 1 | AA27: 1 | AB27: 1 | AE27: 0 | AF27: 0 | AG27: 1 | AU27: =SUM(E27:AT27) -> 18
B28: 9 | AU28: =SUM(E28:AT28) -> 0
B29: 10 | AU29: =SUM(E29:AT29) -> 0
B30: 8 | C30: TOTAL G2 | E30: =SUM(E20:E29) -> 6 | F30: =SUM(F20:F29) -> 8 | G30: =SUM(G20:G29) -> 6 | H30: =SUM(H20:H29) -> 8 | I30: =SUM(I20:I29) -> 8 | J30: =SUM(J20:J29) -> 7 | K30: =SUM(K20:K29) -> 0 | L30: =SUM(L20:L29) -> 0 | ... AT30: =SUM(AT20:AT29) -> 0
E32: 45913 | F32: =E32+7 -> 45920 | G32: =F32+7 -> 45927 | H32: =G32+7 -> 45934 | I32: =H32+7 -> 45941 | J32: =I32+7 -> 45948 | K32: =J32+7 -> 45955 | L32: =K32+7 -> 45962 | M32: =L32+7 -> 45969 | ... AT32: =AS32+7 -> 46200
A34: SAMEDI 10h | B34: SAMEDI 10h | E34: S1 | F34: S2 | G34: S3 | H34: S4 | I34: S5 | J34: S6 | K34: V | L34: V | M34: S7 | N34: S8 | O34: S9 | P34: S10 | Q34: S11 | R34: S12 | S34: S13 | T34: V | U34: V | V34: S14 | W34: S15 | X34: S16 | Y34: S17 | Z34: S18 | AA34: S19 | AB34: S20 | AC34: V | AD34: V | AE34: S21 | AF34: S22 | AG34: S23 | AH34: S24 | AI34: S25 | AJ34: S26 | AK34: V | AL34: V | AM34: S27 | AN34: S28 | AO34: F | AP34: S29 | AQ34: S30 | AR34: S31 | AS34: S32 | AT34: S33 | AU34: =SUM(E34:AT34) -> 0
B35: 1 | C35: MARTIN Noah | D35: U5 | E35: 1 | F35: 1 | G35: 0 | H35: 1 | I35: 1 | J35: 1 | M35: 1 | N35: 1 | O35: 1 | P35: 1 | Q35: 1 | R35: Annulé | S35: 1 | V35: 1 | W35: 1 | X35: 1 | Y35: Annulé | Z35: 1 | AA35: 0 | AB35: 1 | AE35: 1 | AF35: 1 | AG35: 1 | AU35: =SUM(E35:AT35) -> 19
B36: 2 | C36: MICHOT DA CONCEICAO Keyian | D36: U5 | E36: 1 | F36: 1 | G36: 0 | H36: 1 | I36: 1 | J36: 1 | M36: 0 | N36: 1 | O36: 1 | P36: 1 | Q36: 0 | R36: ADN | S36: 0 | V36: 0 | W36: 0 | X36: 0 | Y36: PB éduc | Z36: 1 | AA36: 1 | AB36: 1 | AE36: 1 | AF36: 1 | AG36: 1 | AU36: =SUM(E36:AT36) -> 14
B37: 3 | C37: FRAIKIN Gaspard | D37: U5 | E37: 1 | F37: 1 | G37: 1 | H37: 1 | I37: 1 | J37: 1 | M37: 0 | N37: 1 | O37: 1 | P37: 1 | Q37: 1 | S37: 0 | V37: 0 | W37: 1 | X37: 1 | Z37: 1 | AA37: 1 | AB37: 1 | AE37: 1 | AF37: 1 | AG37: 1 | AU37: =SUM(E37:AT37) -> 18
B38: 4 | C38: SIMON Taïryk | D38: U5 | E38: 1 | F38: 1 | G38: 1 | H38: 1 | I38: 1 | J38: 0 | M38: 0 | N38: 1 | O38: 1 | P38: 0 | Q38: 1 | S38: 0 | V38: 0 | W38: 1 | X38: 0 | Z38: 1 | AA38: 0 | AB38: 0 | AE38: 0 | AF38: 1 | AG38: 1 | AU38: =SUM(E38:AT38) -> 12
B39: 5 | C39: AHITOUR Youssef | D39: U5 | E39: 1 | F39: 1 | G39: 1 | H39: 1 | I39: 1 | J39: 1 | M39: 1 | N39: 1 | O39: 1 | P39: 1 | Q39: 1 | S39: 1 | V39: 1 | W39: 1 | X39: 1 | Z39: 1 | AA39: 1 | AB39: 1 | AE39: 1 | AF39: 1 | AG39: 1 | AU39: =SUM(E39:AT39) -> 21
B40: 6 | C40: VANGOUT Isaiah | D40: U5 | E40: 1 | F40: 1 | G40: 1 | H40: 1 | I40: 1 | J40: 1 | M40: 1 | N40: 1 | O40: 1 | P40: 1 | Q40: 1 | S40: 1 | V40: 1 | W40: 1 | X40: 1 | Z40: 1 | AA40: 1 | AB40: 1 | AE40: 1 | AF40: 1 | AG40: 1 | AU40: =SUM(E40:AT40) -> 21
B41: 7 | C41: FRANCOIS Noah | D41: U5 | E41: 1 | F41: 1 | G41: 1 | H41: 1 | I41: 1 | J41: 1 | M41: 1 | N41: 1 | O41: 1 | P41: 1 | Q41: 1 | S41: 1 | V41: 1 | W41: 1 | X41: 1 | Z41: 1 | AA41: 1 | AB41: 1 | AE41: 1 | AF41: 1 | AG41: 1 | AU41: =SUM(E41:AT41) -> 21
B42: 8 | C42: KINANKAZI Kimya | D42: U5 | E42: 1 | F42: 1 | G42: 0 | H42: 1 | I42: 1 | J42: 0 | M42: 1 | N42: 1 | O42: 1 | P42: 1 | Q42: 0 | S42: 0 | V42: 1 | W42: 1 | X42: 0 | Z42: 1 | AA42: 1 | AB42: 0 | AE42: 0 | AF42: 1 | AG42: 1 | AU42: =SUM(E42:AT42) -> 14
B43: 9 | AU43: =SUM(E43:AT43) -> 0
B44: 10
B45: 8 | C45: TOTAL G3 | E45: =SUM(E35:E44) -> 8 | F45: =SUM(F35:F44) -> 8 | G45: =SUM(G35:G44) -> 5 | H45: =SUM(H35:H44) -> 8 | I45: =SUM(I35:I44) -> 8 | J45: =SUM(J35:J44) -> 6 | K45: =SUM(K35:K44) -> 0 | L45: =SUM(L35:L44) -> 0 | ... AT45: =SUM(AT35:AT44) -> 0
...

Sheet LUNDI 17H30 Présence
C1: LUNDI 17H30
E4: 45908 | F4: =E4+7 -> 45915 | G4: =F4+7 -> 45922 | H4: =G4+7 -> 45929 | I4: =H4+7 -> 45936 | J4: =I4+7 -> 45943 | K4: =J4+7 -> 45950 | L4: =K4+7 -> 45957 | M4: =L4+7 -> 45964 | ... AT4: =AS4+7 -> 46195
C5: ='BABY Présence'!C4 -> MAJ LISTE 11/03 : 12h15
A6: 1er groupe | C6: TOTAL INSCRIPTION EDF : | D6: ='BABY Présence'!D5 -> 321 | E6: S1 | F6: S2 | G6: S3 | H6: S4 | I6: S5 | J6: S6 | K6: V | L6: V | M6: S7 | N6: S8 | O6: S9 | P6: S10 | Q6: S11 | R6: S12 | S6: S13 | T6: V | U6: V | V6: S14 | W6: S15 | X6: S16 | Y6: S17 | Z6: S18 | AA6: S19 | AB6: S20 | AC6: V | AD6: V | AE6: S21 | AF6: S22 | AG6: S23 | AH6: S24 | AI6: S25 | AJ6: S26 | AK6: V | AL6: V | AM6: S27 | AN6: S28 | AO6: F | AP6: S29 | AQ6: S30 | AR6: S31 | AS6: S32 | AT6: S33
B7: 1 | C7: GRAY Louis | D7: U10 | E7: 1 | F7: 1 | G7: 1 | H7: 1 | I7: 1 | J7: 1 | M7: 1 | N7: 0 | O7: 1 | P7: 1 | Q7: 1 | R7: 1 | S7: 1 | V7: 1 | W7: 1 | X7: 1 | Y7: 1 | Z7: 1 | AA7: 1 | AB7: 1 | AE7: 1 | AF7: 1 | AG7: 1 | AU7: =SUM(I7:AT7) -> 18
B8: 2 | C8: LECEA Joseph | D8: U10 | E8: 0 | F8: 1 | G8: 0 | H8: 1 | I8: 1 | J8: 1 | M8: 1 | N8: 0 | O8: 1 | P8: 1 | Q8: 1 | R8: 0 | S8: 1 | V8: 1 | W8: 0 | X8: 1 | Y8: 1 | Z8: 0 | AA8: 1 | AB8: 1 | AE8: 1 | AF8: 1 | AG8: 1 | AU8: =SUM(I8:AT8) -> 15
B9: 3 | C9: SALAME Bassam | D9: U10 | E9: 0 | F9: 1 | G9: 0 | H9: 1 | I9: 1 | J9: 1 | M9: 1 | N9: 1 | O9: 1 | P9: 1 | Q9: 1 | R9: 1 | S9: 1 | V9: 0 | W9: 1 | X9: 1 | Y9: 1 | Z9: 1 | AA9: 1 | AB9: 1 | AE9: 0 | AF9: 0 | AG9: 0 | AU9: =SUM(I9:AT9) -> 15
B10: 4 | C10: GUILLETAT Seyf | D10: U10 | E10: 1 | F10: 1 | G10: 1 | H10: 1 | I10: 1 | J10: 1 | M10: 0 | N10: 0 | O10: 1 | P10: 1 | Q10: 1 | R10: 0 | S10: 1 | V10: 1 | W10: 1 | X10: 1 | Y10: 1 | Z10: 1 | AA10: 1 | AB10: 0 | AE10: 0 | AF10: 0 | AG10: 1 | AU10: =SUM(I10:AT10) -> 13
B11: 5 | C11: COINTE-FOURRIER Axel | D11: U10 | E11: 0 | F11: 1 | G11: 1 | H11: 1 | I11: 0 | J11: 1 | M11: 1 | N11: 1 | O11: 1 | P11: 1 | Q11: 1 | R11: 1 | S11: 0 | V11: 1 | W11: 1 | X11: 1 | Y11: 0 | Z11: 1 | AA11: 1 | AB11: 1 | AE11: 1 | AF11: 1 | AG11: 1 | AU11: =SUM(I11:AT11) -> 16
B12: 6 | C12: RODRIGUEZ Clément | D12: U11 | E12: 1 | F12: 1 | G12: 1 | H12: 1 | I12: 1 | J12: 1 | M12: 1 | N12: 0 | O12: 1 | P12: 0 | Q12: 0 | R12: 1 | S12: 1 | V12: 1 | W12: 1 | X12: 1 | Y12: 1 | Z12: 1 | AA12: 1 | AB12: 1 | AE12: 1 | AF12: 0 | AG12: 1 | AU12: =SUM(I12:AT12) -> 15
B13: 7 | C13: SUN Bastien | D13: U11 | E13: 1 | F13: 1 | G13: 1 | H13: 1 | I13: 1 | J13: 1 | M13: 1 | N13: 1 | O13: 1 | P13: 1 | Q13: 1 | R13: 1 | S13: 1 | V13: 1 | W13: 1 | X13: 1 | Y13: 1 | Z13: 0 | AA13: 1 | AB13: 0 | AE13: 1 | AF13: 1 | AG13: 0 | AU13: =SUM(I13:AT13) -> 16
B14: 8 | C14: MOUMEN Maher | D14: U11 | E14: 1 | F14: 1 | G14: 1 | H14: 1 | I14: 1 | J14: 1 | M14: 1 | N14: 1 | O14: 1 | P14: 1 | Q14: 1 | R14: 1 | S14: 0 | V14: 1 | W14: 1 | X14: 1 | Y14: 1 | Z14: 1 | AA14: 1 | AB14: 1 | AE14: 1 | AF14: 1 | AG14: 1 | AU14: =SUM(I14:AT14) -> 18
B15: 9 | C15: MOUMEN Wael | D15: U11 | E15: 1 | F15: 1 | G15: 1 | H15: 1 | I15: 1 | J15: 1 | M15: 1 | N15: 1 | O15: 1 | P15: 1 | Q15: 1 | R15: 1 | S15: 0 | V15: 1 | W15: 1 | X15: 1 | Y15: 1 | Z15: 1 | AA15: 1 | AB15: 1 | AE15: 1 | AF15: 1 | AG15: 1 | AU15: =SUM(I15:AT15) -> 18
B16: 10 | C16: AZARYOUH Ismael | D16: U11 | E16: 1 | F16: 0 | G16: 1 | H16: 1 | I16: 1 | J16: 1 | M16: 1 | N16: 1 | O16: 1 | P16: 1 | Q16: 1 | R16: 1 | S16: 1 | V16: 1 | W16: 1 | X16: 0 | Y16: 1 | Z16: 1 | AA16: 0 | AB16: 0 | AE16: 0 | AF16: 1 | AG16: 1 | AU16: =SUM(I16:AT16) -> 15
B17: 11 | C17: ZERROUKI Aymen | D17: U11 | E17: 0 | F17: 0 | G17: 0 | H17: 0 | I17: 0 | J17: 0 | M17: 1 | N17: 1 | O17: 1 | P17: 1 | Q17: 1 | R17: 1 | S17: 0 | V17: 1 | W17: 0 | X17: 0 | Y17: 0 | Z17: 0 | AA17: 0 | AB17: 0 | AE17: 0 | AF17: 0 | AG17: 0 | AU17: =SUM(I17:AT17) -> 7
B18: 12 | C18: FATY Noha | D18: U12 | E18: 1 | F18: 1 | G18: 1 | H18: 1 | I18: 1 | J18: 0 | M18: 1 | N18: 1 | O18: 1 | P18: 1 | Q18: 1 | R18: 0 | S18: 1 | V18: 1 | W18: 1 | X18: 1 | Y18: 1 | Z18: 1 | AA18: 1 | AB18: 0 | AE18: 1 | AF18: 1 | AG18: 1 | AU18: =SUM(I18:AT18) -> 16
... B20: 14 | C20: BECKER Kolja | D20: U11 | E20: 0 | F20: 0 | G20: 0 | H20: 0 | I20: 0 | J20: 0 | M20: 0 | N20: 0 | O20: 0 | P20: 0 | Q20: 0 | R20: 0 | S20: 0 | V20: 0 | W20: 1 | X20: 1 | Y20: 1 | Z20: 0 | AA20: 1 | AB20: 1 | AE20: 1 | AF20: 1 | AG20: 1 | AU20: =SUM(I20:AT20) -> 8
B21: 15 | AU21: =SUM(I21:AT21) -> 0
B22: 16 | AU22: =SUM(I22:AT22) -> 0
B23: 14 | C23: TOTAL G1 | E23: =COUNTIF(E7:E22,"1") -> 9 | F23: =COUNTIF(F7:F22,"1") -> 11 | G23: =COUNTIF(G7:G22,"1") -> 9 | H23: =COUNTIF(H7:H22,"1") -> 12 | I23: =COUNTIF(I7:I22,"1") -> 11 | J23: =COUNTIF(J7:J22,"1") -> 11 | K23: =COUNTIF(K7:K22,"1") -> 0 | L23: =COUNTIF(L7:L22,"1") -> 0 | ... AP23: =COUNTIF(AP7:AP22,"1") -> 0
E24: 45908 | F24: =E24+7 -> 45915 | G24: =F24+7 -> 45922 | H24: =G24+7 -> 45929 | I24: =H24+7 -> 45936 | J24: =I24+7 -> 45943 | K24: =J24+7 -> 45950 | L24: =K24+7 -> 45957 | M24: =L24+7 -> 45964 | ... AT24: =AS24+7 -> 46195
E26: S1 | F26: S2 | G26: S3 | H26: S4 | I26: S5 | J26: S6 | K26: V | L26: V | M26: S7 | N26: S8 | O26: S9 | P26: S10 | Q26: S11 | R26: S12 | S26: S13 | T26: V | U26: V | V26: S14 | W26: S15 | X26: S16 | Y26: S17 | Z26: S18 | AA26: S19 | AB26: S20 | AC26: V | AD26: V | AE26: S21 | AF26: S22 | AG26: S23 | AH26: S24 | AI26: S25 | AJ26: S26 | AK26: V | AL26: V | AM26: S27 | AN26: S28 | AO26: F | AP26: S29 | AQ26: S30 | AR26: S31 | AS26: S32 | AT26: S33
A27: 2è groupe | B27: 1 | C27: NIEMBRO Pedro (Lille-Bondues) | D27: U12 | AU27: =SUM(I27:AT27) -> 0
B28: 2 | C28: LEMOINE Marcel (Tlse Montaudran) | D28: U11 | E28: 1 | F28: 1 | G28: 0 | H28: 0 | I28: 1 | J28: 1 | M28: 0 | N28: 1 | O28: 1 | P28: 1 | Q28: 1 | R28: 1 | S28: 0 | V28: 1 | W28: 0 | X28: 1 | Y28: 1 | AU28: =SUM(I28:AT28) -> 10
B29: 3 | AU29: =SUM(I29:AT29) -> 0
B30: 4 | AU30: =SUM(I30:AT30) -> 0
B31: 5 | AU31: =SUM(I31:AT31) -> 0
B32: 6 | AU32: =SUM(I32:AT32) -> 0
B33: 7 | AU33: =SUM(I33:AT33) -> 0
B34: 8 | AU34: =SUM(I34:AT34) -> 0
B35: 9 | AU35: =SUM(I35:AT35) -> 0
B36: 10 | AU36: =SUM(I36:AT36) -> 0
B37: 11 | AU37: =SUM(I37:AT37) -> 0
B38: 12 | AU38: =SUM(I38:AT38) -> 0
B39: 13 | AU39: =SUM(I39:AT39) -> 0
B40: 14 | AU40: =SUM(I40:AT40) -> 0
... B42: 16 | AU42: =SUM(I42:AT42) -> 0
B43: 1 | C43: TOTAL G2 | E43: =COUNTIF(E27:E42,"1") -> 1 | F43: =COUNTIF(F27:F42,"1") -> 1 | G43: =COUNTIF(G27:G42,"1") -> 0 | H43: =COUNTIF(H27:H42,"1") -> 0 | I43: =COUNTIF(I27:I42,"1") -> 1 | J43: =COUNTIF(J27:J42,"1") -> 1 | K43: =COUNTIF(K27:K42,"1") -> 0 | L43: =COUNTIF(L27:L42,"1") -> 0 | ... AP43: =COUNTIF(AP27:AP42,"1") -> 0
C45: =SUM(B23+B43) -> 15

Sheet MARDI 17H30 Présence
C1: MARDI 17H30
E4: 45909 | F4: =E4+7 -> 45916 | G4: =F4+7 -> 45923 | H4: =G4+7 -> 45930 | I4: =H4+7 -> 45937 | J4: =I4+7 -> 45944 | K4: =J4+7 -> 45951 | L4: =K4+7 -> 45958 | M4: =L4+7 -> 45965 | ... AT4: =AS4+7 -> 46196
C5: ='BABY Présence'!C4 -> MAJ LISTE 11/03 : 12h15
A6: 1er groupe | C6: TOTAL INSCRIPTION EDF : | D6: ='BABY Présence'!D5 -> 321 | E6: S1 | F6: S2 | G6: S3 | H6: S4 | I6: S5 | J6: S6 | K6: V | L6: V | M6: S7 | N6: S8 | O6: S9 | P6: S10 | Q6: S11 | R6: S12 | S6: S13 | T6: V | U6: V | V6: S14 | W6: S15 | X6: S16 | Y6: S17 | Z6: S18 | AA6: S19 | AB6: S20 | AC6: V | AD6: V | AE6: S21 | AF6: S22 | AG6: S23 | AH6: S24 | AI6: S25 | AJ6: S26 | AK6: V | AL6: V | AM6: S27 | AN6: S28 | AO6: F | AP6: S29 | AQ6: S30 | AR6: S31 | AS6: S32 | AT6: S33
B7: 1 | C7: GHACHI TAILLARD Naël | D7: U6 | E7: 1 | F7: 0 | G7: 0 | H7: 1 | I7: 1 | J7: 1 | M7: 0 | N7: 0 | O7: 1 | P7: 1 | Q7: 1 | R7: 1 | S7: 1 | V7: 1 | W7: 1 | X7: 1 | Y7: 1 | Z7: 1 | AA7: 1 | AD7: 0 | AE7: 1 | AF7: 1 | AG7: 1 | AU7: =SUM(I7:AT7) -> 16
B8: 2 | C8: PUJOL Elio | D8: U6 | E8: 0 | F8: 0 | G8: 1 | H8: 1 | I8: 0 | J8: 0 | M8: 1 | N8: 1 | O8: 1 | P8: 1 | Q8: 1 | R8: 1 | S8: 1 | V8: 1 | W8: 1 | X8: 0 | Y8: 1 | Z8: 1 | AA8: 1 | AD8: 1 | AE8: 0 | AF8: 0 | AG8: 0 | AU8: =SUM(I8:AT8) -> 13
B9: 3 | C9: BRUGAT Mathias | D9: U6 | E9: 1 | F9: 1 | G9: 0 | H9: 1 | I9: 1 | J9: 1 | M9: 1 | N9: 1 | O9: 1 | P9: 1 | Q9: 1 | R9: 1 | S9: 1 | V9: 1 | W9: 1 | X9: 0 | Y9: 0 | Z9: 1 | AA9: 1 | AB9: 1 | AD9: 1 | AE9: 1 | AF9: 1 | AG9: 1 | AU9: =SUM(I9:AT9) -> 18
B10: 4 | C10: MAGNIN Jade | D10: U7 | E10: 1 | F10: 1 | G10: 0 | H10: 1 | I10: 1 | J10: 1 | M10: 0 | N10: 1 | O10: 1 | P10: 1 | Q10: 1 | R10: 1 | S10: 1 | V10: 1 | W10: 0 | X10: 1 | Y10: 1 | Z10: 1 | AA10: 0 | AD10: 1 | AE10: 1 | AF10: 1 | AG10: 0 | AU10: =SUM(I10:AT10) -> 15
B11: 5 | C11: MAGNIN Sophie | D11: U7 | E11: 1 | F11: 1 | G11: 1 | H11: 1 | I11: 1 | J11: 0 | M11: 1 | N11: 0 | O11: 1 | P11: 1 | Q11: 0 | R11: 0 | S11: 0 | V11: 0 | W11: 0 | X11: 1 | Y11: 1 | Z11: 1 | AA11: 1 | AD11: 1 | AE11: 1 | AF11: 1 | AG11: 0 | AU11: =SUM(I11:AT11) -> 11
B12: 6 | C12: AMSELEM Ishay | D12: U7 | E12: 1 | F12: 0 | G12: 1 | H12: 1 | I12: 1 | J12: 1 | M12: 0 | N12: 0 | O12: 1 | P12: 1 | Q12: 1 | R12: 1 | S12: 0 | V12: 1 | W12: 1 | X12: 1 | Y12: 1 | Z12: 1 | AA12: 1 | AB12: 1 | AD12: 0 | AE12: 0 | AF12: 1 | AG12: 1 | AU12: =SUM(I12:AT12) -> 15
B13: 7 | C13: BENZITOUNI Kamïl | D13: U7 | E13: 1 | F13: 0 | G13: 1 | H13: 1 | I13: 1 | J13: 1 | M13: 1 | N13: 1 | O13: 0 | P13: 1 | Q13: 1 | R13: 1 | S13: 1 | V13: 1 | W13: 1 | X13: 0 | Y13: 1 | Z13: 1 | AA13: 1 | AB13: 1 | AD13: 1 | AE13: 1 | AF13: 1 | AG13: 0 | AU13: =SUM(I13:AT13) -> 17
B14: 8 | AU14: =SUM(I14:AT14) -> 0
B15: 9 | AU15: =SUM(I15:AT15) -> 0
B16: 10 | AU16: =SUM(I16:AT16) -> 0
B17: 11 | AU17: =SUM(I17:AT17) -> 0
B18: 12 | AU18: =SUM(I18:AT18) -> 0
B19: 13 | AU19: =SUM(I19:AT19) -> 0
B20: 14 | AU20: =SUM(I20:AT20) -> 0
B21: 15 | AU21: =SUM(I21:AT21) -> 0
B22: 16 | AU22: =SUM(I22:AT22) -> 0
B23: 6 | C23: TOTAL G1 | E23: =COUNTIF(E7:E22,"1") -> 6 | F23: =COUNTIF(F7:F22,"1") -> 3 | G23: =COUNTIF(G7:G22,"1") -> 4 | H23: =COUNTIF(H7:H22,"1") -> 7 | I23: =COUNTIF(I7:I22,"1") -> 6 | J23: =COUNTIF(J7:J22,"1") -> 5 | K23: =COUNTIF(K7:K22,"1") -> 0 | L23: =COUNTIF(L7:L22,"1") -> 0 | ... AT23: =COUNTIF(AT7:AT22,"1") -> 0
C24: Silvio (stage) - U7 - SD | E24: 45909 | F24: =E24+7 -> 45916 | G24: =F24+7 -> 45923 | H24: =G24+7 -> 45930 | I24: =H24+7 -> 45937 | J24: =I24+7 -> 45944 | K24: =J24+7 -> 45951 | L24: =K24+7 -> 45958 | M24: =L24+7 -> 45965 | ... AT24: =AS24+7 -> 46196
E26: S1 | F26: S2 | G26: S3 | H26: S4 | I26: S5 | J26: S6 | K26: V | L26: V | M26: S7 | N26: S8 | O26: S9 | P26: S10 | Q26: S11 | R26: S12 | S26: S13 | T26: V | U26: V | V26: S14 | W26: S15 | X26: S16 | Y26: S17 | Z26: S18 | AA26: S19 | AB26: S20 | AC26: V | AD26: V | AE26: S21 | AF26: S22 | AG26: S23 | AH26: S24 | AI26: S25 | AJ26: S26 | AK26: V | AL26: V | AM26: S27 | AN26: S28 | AO26: F | AP26: S29 | AQ26: S30 | AR26: S31 | AS26: S32 | AT26: S33
A27: 2è groupe | B27: 1 | C27: KHELIF Aaron | D27: U8 | E27: 0 | F27: 1 | G27: 0 | H27: 1 | I27: 0 | J27: 0 | M27: 1 | N27: 0 | O27: 1 | P27: 1 | Q27: 1 | R27: 1 | S27: 1 | V27: 1 | W27: 1 | X27: 1 | Y27: 1 | Z27: 1 | AA27: 1 | AB27: 1 | AE27: 0 | AF27: 1 | AG27: 1 | AU27: =SUM(I27:AT27) -> 15
B28: 2 | C28: HARZALLAH Zakaria | D28: U8 | E28: 1 | F28: 1 | G28: 1 | H28: 1 | I28: 1 | J28: 1 | M28: 1 | N28: 1 | O28: 1 | P28: 1 | Q28: 1 | R28: 1 | S28: 1 | V28: 0 | W28: 1 | X28: 1 | Y28: 1 | Z28: 1 | AA28: 1 | AB28: 1 | AE28: 1 | AF28: 1 | AG28: 1 | AU28: =SUM(I28:AT28) -> 18
B29: 3 | C29: SANCHEZ GUERRERO Lennys | D29: U9 | E29: 1 | F29: 0 | G29: 1 | H29: 1 | I29: 1 | J29: 1 | M29: 1 | N29: 0 | O29: 1 | P29: 0 | Q29: 1 | R29: 1 | S29: 0 | V29: 0 | W29: 1 | X29: 1 | Y29: 1 | Z29: 1 | AA29: 1 | AB29: 1 | AE29: 1 | AF29: 1 | AG29: 1 | AU29: =SUM(I29:AT29) -> 15
B30: 4 | C30: DANOT Maël | D30: U9 | E30: 1 | F30: 1 | G30: 1 | H30: 1 | I30: 1 | J30: 1 | M30: 1 | N30: 0 | O30: 1 | P30: 1 | Q30: 1 | R30: 1 | S30: 0 | V30: 1 | W30: 1 | X30: 1 | Y30: 1 | Z30: 1 | AA30: 1 | AB30: 1 | AE30: 1 | AF30: 1 | AG30: 1 | AU30: =SUM(I30:AT30) -> 17
B31: 5 | C31: OLVERA MARTINEZ Matias Andres | D31: U9 | E31: 1 | F31: 1 | G31: 1 | H31: 1 | I31: 1 | J31: 1 | M31: 1 | N31: 0 | O31: 1 | P31: 1 | Q31: 1 | R31: 1 | S31: 0 | V31: 0 | W31: 1 | X31: 1 | Y31: 1 | Z31: 0 | AA31: 1 | AB31: 1 | AE31: 1 | AF31: 0 | AG31: 1 | AU31: =SUM(I31:AT31) -> 14
B32: 6 | C32: CHALLUT Tom | D32: U9 | E32: 1 | F32: 1 | G32: 1 | H32: 1 | I32: 1 | J32: 1 | M32: 1 | N32: 0 | O32: 1 | P32: 1 | Q32: 1 | R32: 1 | S32: 0 | V32: 1 | W32: 0 | X32: 1 | Y32: 1 | Z32: 1 | AA32: 1 | AB32: 1 | AE32: 0 | AF32: 0 | AG32: 1 | AU32: =SUM(I32:AT32) -> 14
B33: 7 | C33: GUEDJ Joseph | D33: U9 | E33: 1 | F33: 1 | G33: 0 | H33: 0 | I33: 0 | J33: 0 | M33: 1 | N33: 0 | O33: 1 | P33: 0 | Q33: 1 | R33: 1 | S33: 1 | V33: 1 | W33: 1 | X33: 1 | Y33: 1 | Z33: 1 | AA33: 1 | AB33: 1 | AE33: 1 | AF33: 1 | AG33: 1 | AU33: =SUM(I33:AT33) -> 15
B34: 8 | C34: BENHADDOU Imrane | D34: U9 | E34: 1 | F34: 1 | G34: 1 | H34: 1 | I34: 1 | J34: 1 | M34: 1 | N34: 0 | O34: 1 | P34: 1 | Q34: 1 | R34: 1 | S34: 1 | V34: 1 | W34: 1 | X34: 1 | Y34: 1 | Z34: 1 | AA34: 0 | AB34: 1 | AE34: 1 | AF34: 1 | AG34: 1 | AU34: =SUM(I34:AT34) -> 17
B35: 9 | C35: GHACHI TAILLARD Noé | D35: U9 | E35: 1 | F35: 1 | G35: 1 | H35: 1 | I35: 1 | J35: 1 | M35: 1 | N35: 0 | O35: 1 | P35: 1 | Q35: 1 | R35: 1 | S35: 1 | V35: 1 | W35: 1 | X35: 1 | Y35: 1 | Z35: 1 | AA35: 1 | AB35: 1 | AE35: 1 | AF35: 1 | AG35: 1 | AU35: =SUM(I35:AT35) -> 18
B36: 10 | C36: PUJOL Timéo | D36: U9 | E36: 1 | F36: 1 | G36: 0 | H36: 1 | I36: 0 | J36: 1 | M36: 1 | N36: 0 | O36: 1 | P36: 0 | Q36: 1 | R36: 1 | S36: 1 | V36: 0 | W36: 1 | X36: 1 | Y36: 1 | Z36: 1 | AA36: 0 | AE36: 1 | AF36: 0 | AG36: 1 | AU36: =SUM(I36:AT36) -> 12
B37: 11 | C37: DINH Aaron | D37: U8 | E37: 0 | F37: 0 | G37: 0 | H37: 0 | I37: 0 | J37: 0 | M37: 0 | N37: 0 | O37: 0 | P37: 0 | Q37: 1 | R37: 1 | S37: 1 | V37: 0 | W37: 1 | X37: 1 | Y37: 1 | Z37: 1 | AA37: 1 | AB37: 1 | AE37: 1 | AF37: 1 | AG37: 1 | AU37: =SUM(I37:AT37) -> 12
B38: 12 | AU38: =SUM(I38:AT38) -> 0
B39: 13 | AU39: =SUM(I39:AT39) -> 0
B40: 14 | AU40: =SUM(I40:AT40) -> 0
B41: 15 | AU41: =SUM(I41:AT41) -> 0
B42: 16 | AU42: =SUM(I42:AT42) -> 0
B43: 11 | C43: TOTAL G2 | E43: =COUNTIF(E27:E42,"1") -> 9 | F43: =COUNTIF(F27:F42,"1") -> 9 | G43: =COUNTIF(G27:G42,"1") -> 7 | H43: =COUNTIF(H27:H42,"1") -> 9 | I43: =COUNTIF(I27:I42,"1") -> 7 | J43: =COUNTIF(J27:J42,"1") -> 8 | K43: =COUNTIF(K27:K42,"1") -> 0 | L43: =COUNTIF(L27:L42,"1") -> 0 | ... AT43: =COUNTIF(AT27:AT42,"1") -> 0
...

Sheet Feuil1

Sheet MERCREDI 14h Présence
C1: MERCREDI 14H00
E4: 45910 | F4: =E4+7 -> 45917 | G4: =F4+7 -> 45924 | H4: =G4+7 -> 45931 | I4: =H4+7 -> 45938 | J4: =I4+7 -> 45945 | K4: =J4+7 -> 45952 | L4: =K4+7 -> 45959 | M4: =L4+7 -> 45966 | ... AT4: =AS4+7 -> 46197
C5: ='BABY Présence'!C4 -> MAJ LISTE 11/03 : 12h15
A6: 1er groupe | C6: TOTAL INSCRIPTION EDF : | D6: ='BABY Présence'!D5 -> 321 | E6: S1 | F6: S2 | G6: S3 | H6: S4 | I6: S5 | J6: S6 | K6: V | L6: V | M6: S7 | N6: S8 | O6: S9 | P6: S10 | Q6: S11 | R6: S12 | S6: S13 | T6: V | U6: V | V6: S14 | W6: S15 | X6: S16 | Y6: S17 | Z6: S18 | AA6: S19 | AB6: S20 | AC6: V | AD6: V | AE6: S21 | AF6: S22 | AG6: S23 | AH6: S24 | AI6: S25 | AJ6: S26 | AK6: V | AL6: V | AM6: S27 | AN6: S28 | AO6: F | AP6: S29 | AQ6: S30 | AR6: S31 | AS6: S32 | AT6: S33 | AU6: =SUM(I6:AT6) -> 0
B7: 1 | C7: BARCELO Pablo | D7: U6 | E7: 1 | F7: 1 | G7: 1 | H7: 1 | I7: 1 | J7: 1 | M7: 0 | N7: 0 | O7: 1 | P7: 1 | Q7: 1 | R7: 0 | S7: 0 | V7: 0 | W7: 1 | X7: 1 | Y7: 0 | Z7: 1 | AA7: 1 | AB7: 1 | AD7: 0 | AE7: 1 | AF7: 1 | AG7: 1 | AU7: =SUM(I7:AT7) -> 13
B8: 2 | C8: MORIN NGUYEN Milo | D8: U6 | E8: 1 | F8: 1 | G8: 0 | H8: 1 | I8: 1 | J8: 0 | M8: 1 | N8: 1 | O8: 1 | P8: 1 | Q8: 1 | R8: 1 | S8: 1 | V8: 1 | W8: 1 | X8: 1 | Y8: 1 | Z8: 0 | AA8: 0 | AB8: 1 | AD8: 1 | AE8: 1 | AF8: 1 | AG8: 1 | AU8: =SUM(I8:AT8) -> 17
B9: 3 | C9: GARCIA LOPEZ Carlos | D9: U6 | E9: 1 | F9: 1 | G9: 1 | H9: 1 | I9: 1 | J9: 1 | M9: 1 | N9: 1 | O9: 1 | P9: 1 | Q9: 1 | R9: 0 | S9: 0 | V9: 1 | W9: 0 | X9: 1 | Y9: 1 | Z9: 1 | AA9: 1 | AB9: 1 | AD9: 0 | AE9: 1 | AF9: 1 | AG9: 1 | AU9: =SUM(I9:AT9) -> 16
B10: 4 | C10: ANDRE Salomon | D10: U6 | E10: 1 | F10: 0 | G10: 0 | H10: 1 | I10: 1 | J10: 1 | M10: 1 | N10: 0 | O10: 1 | P10: 1 | Q10: 1 | R10: 0 | S10: 0 | V10: 0 | W10: 0 | X10: 0 | Y10: 1 | Z10: 1 | AA10: 1 | AB10: 0 | AD10: 0 | AE10: 1 | AF10: 1 | AG10: 1 | AU10: =SUM(I10:AT10) -> 12
B11: 5 | C11: RAMOS AMAT Paolo | D11: U6 | E11: 0 | F11: 0 | G11: 0 | H11: 1 | I11: 1 | J11: 1 | M11: 0 | N11: 0 | O11: 1 | P11: 0 | Q11: 1 | R11: 1 | S11: 1 | V11: 1 | W11: 1 | X11: 1 | Y11: 1 | Z11: 0 | AA11: 0 | AB11: 0 | AD11: 1 | AE11: 0 | AF11: 0 | AG11: 0 | AU11: =SUM(I11:AT11) -> 11
B12: 6 | C12: BALLET Akeem | D12: U6 | E12: 1 | F12: 1 | G12: 0 | H12: 1 | I12: 0 | J12: 1 | M12: 0 | N12: 1 | O12: 0 | P12: 1 | Q12: 1 | R12: 1 | S12: 1 | V12: 1 | W12: 1 | X12: 1 | Y12: 1 | Z12: 1 | AA12: 1 | AB12: 1 | AD12: 1 | AE12: 0 | AF12: 0 | AG12: 1 | AU12: =SUM(I12:AT12) -> 15
B13: 7 | C13: AZUELOS Marceau | D13: U7 | E13: 1 | F13: 0 | G13: 1 | H13: 1 | I13: 1 | J13: 1 | M13: 1 | N13: 1 | O13: 1 | P13: 1 | Q13: 1 | R13: 0 | S13: 1 | V13: 1 | W13: 1 | X13: 1 | Y13: 1 | Z13: 1 | AA13: 1 | AB13: 1 | AD13: 1 | AE13: 1 | AF13: 1 | AG13: 1 | AU13: =SUM(I13:AT13) -> 19
B14: 8 | C14: SYED Adem | D14: U7 | E14: 0 | F14: 1 | G14: 0 | H14: 1 | I14: 1 | J14: 1 | M14: 1 | N14: 1 | O14: 1 | P14: 1 | Q14: 1 | R14: 1 | S14: 1 | V14: 1 | W14: 1 | X14: 0 | Y14: 1 | Z14: 1 | AA14: 1 | AB14: 0 | AD14: 1 | AE14: 0 | AF14: 1 | AG14: 1 | AU14: =SUM(I14:AT14) -> 17
B15: 9 | C15: CARFANTAN Gaspar | D15: U7 | E15: 0 | F15: 1 | G15: 1 | H15: 1 | I15: 1 | J15: 1 | M15: 1 | N15: 1 | O15: 1 | P15: 1 | Q15: 1 | R15: 1 | S15: 1 | V15: 1 | W15: 1 | X15: 1 | Y15: 1 | Z15: 1 | AA15: 1 | AB15: 1 | AE15: 1 | AF15: 1 | AG15: 1 | AU15: =SUM(I15:AT15) -> 19
B16: 10 | C16: CALOIN Chris | D16: U7 | E16: 0 | F16: 0 | G16: 0 | H16: 0 | I16: 0 | J16: 0 | M16: 0 | N16: 0 | O16: 0 | P16: 0 | Q16: 0 | R16: 0 | S16: 0 | V16: 0 | W16: 0 | X16: 0 | Y16: 1 | Z16: 1 | AA16: 1 | AB16: 1 | AE16: 1 | AF16: 1 | AG16: 1 | AU16: =SUM(I16:AT16) -> 7
B17: 11 | C17: SABOUR Kamil | D17: U6 | E17: 0 | F17: 0 | G17: 0 | H17: 0 | I17: 0 | J17: 0 | M17: 0 | N17: 0 | O17: 0 | P17: 0 | Q17: 0 | R17: 0 | S17: 0 | V17: 0 | W17: 0 | X17: 0 | Y17: 0 | Z17: 0 | AA17: 0 | AB17: 1 | AE17: 1 | AF17: 1 | AG17: 1 | AU17: =SUM(I17:AT17) -> 4
B18: 12 | AU18: =SUM(I18:AT18) -> 0
B19: 13 | AU19: =SUM(I19:AT19) -> 0
B20: 14 | AU20: =SUM(I20:AT20) -> 0
B21: 15 | AU21: =SUM(I21:AT21) -> 0
B22: 16 | AU22: =SUM(I22:AT22) -> 0
B23: 11 | C23: TOTAL G1 | E23: =COUNTIF(E7:E22,"1") -> 6 | F23: =COUNTIF(F7:F22,"1") -> 6 | G23: =COUNTIF(G7:G22,"1") -> 4 | H23: =COUNTIF(H7:H22,"1") -> 9 | I23: =COUNTIF(I7:I22,"1") -> 8 | J23: =COUNTIF(J7:J22,"1") -> 8 | K23: =COUNTIF(K7:K22,"1") -> 0 | L23: =COUNTIF(L7:L22,"1") -> 0 | ... AT23: =COUNTIF(AT7:AT22,"1") -> 0 | AU23: =SUM(I23:AT23) -> 150
E24: 45910 | F24: =E24+7 -> 45917 | G24: =F24+7 -> 45924 | H24: =G24+7 -> 45931 | I24: =H24+7 -> 45938 | J24: =I24+7 -> 45945 | K24: =J24+7 -> 45952 | L24: =K24+7 -> 45959 | M24: =L24+7 -> 45966 | ... AT24: =AS24+7 -> 46197
E26: S1 | F26: S2 | G26: S3 | H26: S4 | I26: S5 | J26: S6 | K26: V | L26: V | M26: S7 | N26: S8 | O26: S9 | P26: S10 | Q26: S11 | R26: S12 | S26: S13 | T26: V | U26: V | V26: S14 | W26: S15 | X26: S16 | Y26: S17 | Z26: S18 | AA26: S19 | AB26: S20 | AC26: V | AD26: V | AE26: S21 | AF26: S22 | AG26: S23 | AH26: S24 | AI26: S25 | AJ26: S26 | AK26: V | AL26: V | AM26: S27 | AN26: S28 | AO26: F | AP26: S29 | AQ26: S30 | AR26: S31 | AS26: S32 | AT26: S33 | AU26: =SUM(I26:AT26) -> 0
A27: 2è groupe | B27: 1 | C27: GLANDIER Carl | D27: U8 | E27: 1 | F27: 1 | G27: 1 | H27: 1 | I27: 1 | J27: 1 | M27: 1 | N27: 1 | O27: 1 | P27: 1 | Q27: 1 | R27: 1 | S27: 1 | V27: 1 | W27: 1 | X27: 1 | Y27: 1 | Z27: 1 | AA27: 1 | AB27: 1 | AE27: 1 | AF27: 1 | AG27: 1 | AU27: =SUM(I27:AT27) -> 19
B28: 2 | C28: MITCHELL Arthur | D28: U8 | E28: 1 | F28: 1 | G28: 1 | H28: 1 | I28: 1 | J28: 1 | M28: 1 | N28: 1 | O28: 1 | P28: 1 | Q28: 1 | R28: 1 | S28: 1 | V28: 1 | W28: 1 | X28: 1 | Y28: 1 | Z28: 1 | AA28: 1 | AB28: 1 | AE28: 1 | AF28: 1 | AG28: 1 | AU28: =SUM(I28:AT28) -> 19
B29: 3 | C29: SALAH Gauthier | D29: U8 | E29: 1 | F29: 1 | G29: 1 | H29: 1 | I29: 1 | J29: 1 | M29: 1 | N29: 1 | O29: 1 | P29: 1 | Q29: 1 | R29: 1 | S29: 1 | V29: 1 | W29: 0 | X29: 1 | Y29: 1 | Z29: 1 | AA29: 1 | AB29: 1 | AE29: 1 | AF29: 1 | AG29: 1 | AU29: =SUM(I29:AT29) -> 18
B30: 4 | C30: COULIBALY Adam | D30: U9 | E30: 0 | F30: 0 | G30: 0 | H30: 0 | I30: 1 | J30: 1 | M30: 1 | N30: 1 | O30: 1 | P30: 1 | Q30: 1 | R30: 1 | S30: 0 | V30: 1 | W30: 0 | X30: 0 | Y30: 1 | Z30: 1 | AA30: 0 | AB30: 1 | AE30: 1 | AF30: 1 | AG30: 1 | AU30: =SUM(I30:AT30) -> 15
B31: 5 | C31: MEKDACH Riyad | D31: U9 | E31: 1 | F31: 1 | G31: 1 | H31: 1 | I31: 1 | J31: 0 | M31: 1 | N31: 1 | O31: 0 | P31: 1 | Q31: 0 | R31: 1 | S31: 1 | V31: 1 | W31: 1 | X31: 1 | Y31: 1 | Z31: 1 | AA31: 1 | AB31: 1 | AE31: 1 | AF31: 0 | AG31: 1 | AU31: =SUM(I31:AT31) -> 15
B32: 6 | C32: SI SALAH Mayas | D32: U9 | E32: 0 | F32: 0 | G32: 1 | H32: 1 | I32: 1 | J32: 0 | M32: 1 | N32: 1 | O32: 0 | P32: 1 | Q32: 1 | R32: 1 | S32: 1 | V32: 0 | W32: 1 | X32: 1 | Y32: 1 | Z32: 1 | AA32: 1 | AB32: 1 | AE32: 1 | AF32: 0 | AG32: 1 | AU32: =SUM(I32:AT32) -> 15
B33: 7 | C33: MAZOIN Matisse | D33: U8 | E33: 1 | F33: 1 | G33: 1 | H33: 1 | I33: 1 | J33: 1 | M33: 1 | N33: 1 | O33: 1 | P33: 1 | Q33: 1 | R33: 1 | S33: 1 | V33: 1 | W33: 1 | X33: 1 | Y33: 1 | Z33: 1 | AA33: 0 | AB33: 1 | AE33: 1 | AF33: 1 | AG33: 1 | AU33: =SUM(I33:AT33) -> 18
B34: 8 | C34: LABORIE Romain | D34: U8 | E34: 1 | F34: 1 | G34: 1 | H34: 0 | I34: 1 | J34: 1 | M34: 1 | N34: 1 | O34: 1 | P34: 1 | Q34: 1 | R34: 1 | S34: 1 | V34: 1 | W34: 1 | X34: 1 | Y34: 1 | Z34: 1 | AA34: 1 | AB34: 1 | AE34: 1 | AF34: 1 | AG34: 1 | AU34: =SUM(I34:AT34) -> 19
B35: 9 | C35: DESCUDE Ivan | D35: U8 | E35: 1 | F35: 1 | G35: 1 | H35: 1 | I35: 1 | J35: 1 | M35: 1 | N35: 1 | O35: 1 | P35: 1 | Q35: 0 | R35: 0 | S35: 1 | V35: 1 | W35: 1 | X35: 1 | Y35: 1 | Z35: 1 | AA35: 0 | AB35: 1 | AE35: 1 | AF35: 1 | AG35: 1 | AU35: =SUM(I35:AT35) -> 16
B36: 10 | C36: SCHMITT Baptiste | D36: U8 | E36: 1 | F36: 1 | G36: 1 | H36: 1 | I36: 1 | J36: 1 | M36: 1 | N36: 1 | O36: 1 | P36: 1 | Q36: 1 | R36: 1 | S36: 1 | V36: 1 | W36: 0 | X36: 1 | Y36: 1 | Z36: 1 | AA36: 1 | AB36: 1 | AE36: 0 | AF36: 1 | AG36: 1 | AU36: =SUM(I36:AT36) -> 17
B37: 11 | C37: COUTE Nolan | D37: U9 | E37: 1 | F37: 1 | G37: 1 | H37: 1 | I37: 1 | J37: 1 | M37: 1 | N37: 1 | O37: 1 | P37: 1 | Q37: 1 | R37: 1 | S37: 1 | V37: 1 | W37: 0 | X37: 1 | Y37: 1 | Z37: 0 | AA37: 0 | AB37: 1 | AE37: 1 | AF37: 1 | AG37: 1 | AU37: =SUM(I37:AT37) -> 16
B38: 12 | C38: DIALLO Adam | D38: U7 | E38: 0 | F38: 0 | G38: 0 | H38: 0 | I38: 0 | J38: 0 | M38: 0 | N38: 0 | O38: 1 | P38: 1 | Q38: 0 | R38: 1 | S38: 0 | V38: 1 | W38: 1 | X38: 1 | Y38: 1 | Z38: 1 | AA38: 1 | AB38: 1 | AE38: 1 | AF38: 1 | AG38: 1 | AU38: =SUM(I38:AT38) -> 13
B39: 13 | C39: DE BRITO Raphaël | D39: U8 | E39: 0 | F39: 0 | G39: 0 | H39: 0 | I39: 0 | J39: 0 | M39: 0 | N39: 0 | O39: 0 | P39: 0 | Q39: 0 | R39: 0 | S39: 0 | V39: 0 | W39: 0 | X39: 0 | Y39: 0 | Z39: 0 | AA39: 0 | AB39: 0 | AE39: 0 | AF39: 0 | AG39: 0 | AU39: =SUM(I39:AT39) -> 0
B40: 14 | AU40: =SUM(I40:AT40) -> 0
B41: 15 | AU41: =SUM(I41:AT41) -> 0
B42: 16 | AU42: =SUM(I42:AT42) -> 0
B43: 13 | C43: TOTAL G2 | E43: =COUNTIF(E27:E42,"1") -> 9 | F43: =COUNTIF(F27:F42,"1") -> 9 | G43: =COUNTIF(G27:G42,"1") -> 10 | H43: =COUNTIF(H27:H42,"1") -> 9 | I43: =COUNTIF(I27:I42,"1") -> 11 | J43: =COUNTIF(J27:J42,"1") -> 9 | K43: =COUNTIF(K27:K42,"1") -> 0 | L43: =COUNTIF(L27:L42,"1") -> 0 | ... AT43: =COUNTIF(AT27:AT42,"1") -> 0 | AU43: =SUM(I43:AT43) -> 200
...

Sheet MERCREDI 15h45 Présence 
C1: MERCREDI 15H45
E4: 45910 | F4: =E4+7 -> 45917 | G4: =F4+7 -> 45924 | H4: =G4+7 -> 45931 | I4: =H4+7 -> 45938 | J4: =I4+7 -> 45945 | K4: =J4+7 -> 45952 | L4: =K4+7 -> 45959 | M4: =L4+7 -> 45966 | ... AT4: =AS4+7 -> 46197
C5: ='BABY Présence'!C4 -> MAJ LISTE 11/03 : 12h15
A6: 1er groupe | C6: TOTAL INSCRIPTION EDF : | D6: ='BABY Présence'!D5 -> 321 | E6: S1 | F6: S2 | G6: S3 | H6: S4 | I6: S5 | J6: S6 | K6: V | L6: V | M6: S7 | N6: S8 | O6: S9 | P6: S10 | Q6: S11 | R6: S12 | S6: S13 | T6: V | U6: V | V6: S14 | W6: S15 | X6: S16 | Y6: S17 | Z6: S18 | AA6: S19 | AB6: S20 | AC6: V | AD6: V | AE6: S21 | AF6: S22 | AG6: S23 | AH6: S24 | AI6: S25 | AJ6: S26 | AK6: V | AL6: V | AM6: S27 | AN6: S28 | AO6: F | AP6: S29 | AQ6: S30 | AR6: S31 | AS6: S32 | AT6: S33 | AU6: =SUM(I6:AT6) -> 0
B7: 1 | C7: ABOU LEYLA Youssef | D7: U10 | E7: 1 | F7: 1 | G7: 1 | H7: 1 | I7: 1 | J7: 1 | M7: 1 | N7: 1 | O7: 1 | P7: 1 | Q7: 1 | R7: 1 | S7: 1 | V7: 0 | W7: 1 | X7: 1 | Y7: 1 | AA7: 1 | AB7: 1 | AE7: 1 | AF7: 1 | AG7: 1 | AU7: =SUM(I7:AT7) -> 17
B8: 2 | C8: LEGRAND LHOPITAULT Gabriel | D8: U10 | E8: 1 | F8: 1 | G8: 1 | H8: 1 | I8: 1 | J8: 1 | M8: 1 | N8: 1 | O8: 1 | P8: 1 | Q8: 1 | R8: 1 | S8: 0 | V8: 1 | W8: 1 | X8: 1 | Y8: 0 | AA8: 1 | AB8: 1 | AE8: 1 | AF8: 1 | AG8: 0 | AU8: =SUM(I8:AT8) -> 15
B9: 3 | C9: NGUEMA MEDANG Seth | D9: U10 | E9: 1 | F9: 1 | G9: 1 | H9: 1 | I9: 1 | J9: 1 | M9: 1 | N9: 1 | O9: 1 | P9: 0 | Q9: 1 | R9: 1 | S9: 1 | V9: 1 | W9: 1 | X9: 1 | Y9: 1 | AA9: 0 | AB9: 1 | AE9: 0 | AF9: 1 | AG9: 0 | AU9: =SUM(I9:AT9) -> 14
B10: 4 | C10: MEDALE Joaquim | D10: U10 | E10: 1 | F10: 1 | G10: 1 | H10: 1 | I10: 1 | J10: 1 | M10: 1 | N10: 1 | O10: 1 | P10: 1 | Q10: 1 | R10: 1 | S10: 1 | V10: 0 | W10: 1 | X10: 1 | Y10: 1 | AA10: 1 | AB10: 1 | AE10: 1 | AF10: 1 | AG10: 0 | AU10: =SUM(I10:AT10) -> 16
B11: 5 | C11: BESNARD Noah | D11: U10 | E11: 1 | F11: 1 | G11: 1 | H11: 1 | I11: 1 | J11: 1 | M11: 1 | N11: 1 | O11: 1 | P11: 1 | Q11: 1 | R11: 1 | S11: 1 | V11: 1 | W11: 0 | X11: 0 | Y11: 1 | AA11: 1 | AB11: 1 | AE11: 1 | AF11: 1 | AG11: 1 | AU11: =SUM(I11:AT11) -> 16
B12: 6 | C12: DESPOISSE Louis | D12: U10 | E12: 1 | F12: 1 | G12: 1 | H12: 1 | I12: 1 | J12: 1 | M12: 1 | N12: 1 | O12: 1 | P12: 1 | Q12: 1 | R12: 1 | S12: 0 | V12: 1 | W12: 1 | X12: 1 | Y12: 1 | AA12: 1 | AB12: 1 | AE12: 1 | AF12: 1 | AG12: 1 | AU12: =SUM(I12:AT12) -> 17
B13: 7 | C13: SACADURA DOS SANTOS Thomas | D13: U10 | E13: 1 | F13: 1 | G13: 1 | H13: 1 | I13: 1 | J13: 0 | M13: 1 | N13: 1 | O13: 1 | P13: 1 | Q13: 0 | R13: 1 | S13: 0 | V13: 1 | W13: 1 | X13: 1 | Y13: 1 | AA13: 1 | AB13: 1 | AE13: 1 | AF13: 0 | AG13: 1 | AU13: =SUM(I13:AT13) -> 14
B14: 8 | C14: KARIMI Jad-Liam | D14: U10 | E14: 1 | F14: 1 | G14: 1 | H14: 1 | I14: 1 | J14: 1 | M14: 1 | N14: 1 | O14: 1 | P14: 1 | Q14: 1 | R14: 1 | S14: 1 | V14: 1 | W14: 1 | X14: 1 | Y14: 1 | AA14: 0 | AB14: 1 | AE14: 1 | AF14: 1 | AG14: 1 | AU14: =SUM(I14:AT14) -> 17
B15: 9 | C15: DELGADO Emiliano | D15: U10 | E15: 1 | F15: 0 | G15: 1 | H15: 1 | I15: 1 | J15: 0 | M15: 1 | N15: 1 | O15: 1 | P15: 1 | Q15: 1 | R15: 1 | S15: 0 | V15: 1 | W15: 0 | X15: 0 | Y15: 1 | AA15: 1 | AB15: 1 | AE15: 1 | AF15: 0 | AG15: 0 | AU15: =SUM(I15:AT15) -> 12
B16: 10 | C16: MANNA Gabriel | D16: U10 | E16: 1 | F16: 1 | G16: 1 | H16: 1 | I16: 1 | J16: 1 | M16: 1 | N16: 1 | O16: 1 | P16: 0 | Q16: 1 | R16: 1 | S16: 1 | V16: 1 | W16: 1 | X16: 1 | Y16: 1 | AA16: 1 | AB16: 1 | AE16: 1 | AF16: 1 | AG16: 1 | AU16: =SUM(I16:AT16) -> 17
B17: 11 | C17: FARSI Amir | D17: U10 | E17: 1 | F17: 1 | G17: 1 | H17: 1 | I17: 0 | J17: 0 | M17: 1 | N17: 0 | O17: 1 | P17: 1 | Q17: 1 | R17: 1 | S17: 1 | V17: 1 | W17: 1 | X17: 1 | Y17: 1 | AA17: 0 | AB17: 1 | AE17: 1 | AF17: 0 | AG17: 0 | AU17: =SUM(I17:AT17) -> 12
B18: 12 | C18: AMRI Souleymane | D18: U10 | E18: 0 | F18: 1 | G18: 1 | H18: 1 | I18: 1 | J18: 1 | M18: 1 | N18: 1 | O18: 1 | P18: 1 | Q18: 1 | R18: 1 | S18: 0 | V18: 0 | W18: 1 | X18: 1 | Y18: 1 | AA18: 1 | AB18: 0 | AE18: 1 | AF18: 1 | AG18: 0 | AU18: =SUM(I18:AT18) -> 14
... B21: 15 | C21: AMER Ayman | D21: U10 | E21: 0 | F21: 0 | G21: 0 | H21: 0 | I21: 0 | J21: 0 | M21: 1 | N21: 1 | O21: 1 | P21: 1 | Q21: 1 | R21: 0 | S21: 0 | V21: 1 | W21: 1 | X21: 1 | Y21: 1 | AA21: 1 | AB21: 1 | AE21: 1 | AF21: 1 | AG21: 1 | AU21: =SUM(I21:AT21) -> 14
B22: 16 | C22: AZIZA Sam | D22: U11 | E22: 0 | F22: 0 | G22: 0 | H22: 0 | I22: 0 | J22: 0 | M22: 1 | N22: 1 | O22: 1 | P22: 1 | Q22: 1 | R22: 1 | S22: 1 | V22: 1 | W22: 1 | X22: 1 | Y22: 1 | AA22: 1 | AB22: 1 | AE22: 1 | AF22: 1 | AU22: =SUM(I22:AT22) -> 15
B23: 16 | C23: TOTAL G1 | E23: =COUNTIF(E7:E22,"1") -> 11 | F23: =COUNTIF(F7:F22,"1") -> 11 | G23: =COUNTIF(G7:G22,"1") -> 13 | H23: =COUNTIF(H7:H22,"1") -> 13 | I23: =COUNTIF(I7:I22,"1") -> 13 | J23: =COUNTIF(J7:J22,"1") -> 10 | K23: =COUNTIF(K7:K22,"1") -> 0 | L23: =COUNTIF(L7:L22,"1") -> 0 | ... AT23: =COUNTIF(AT7:AT22,"1") -> 0 | AU23: =SUM(I23:AT23) -> 244
E24: 45910 | F24: =E24+7 -> 45917 | G24: =F24+7 -> 45924 | H24: =G24+7 -> 45931 | I24: =H24+7 -> 45938 | J24: =I24+7 -> 45945 | K24: =J24+7 -> 45952 | L24: =K24+7 -> 45959 | M24: =L24+7 -> 45966 | ... AT24: =AS24+7 -> 46197
E26: S1 | F26: S2 | G26: S3 | H26: S4 | I26: S5 | J26: S6 | K26: V | L26: V | M26: S7 | N26: S8 | O26: S9 | P26: S10 | Q26: S11 | R26: S12 | S26: S13 | T26: V | U26: V | V26: S14 | W26: S15 | X26: S16 | Y26: S17 | Z26: S18 | AA26: S19 | AB26: S20 | AC26: V | AD26: V | AE26: S21 | AF26: S22 | AG26: S23 | AH26: S24 | AI26: S25 | AJ26: S26 | AK26: V | AL26: V | AM26: S27 | AN26: S28 | AO26: F | AP26: S29 | AQ26: S30 | AR26: S31 | AS26: S32 | AT26: S33 | AU26: =SUM(I26:AT26) -> 0
A27: 2è groupe | B27: 1 | C27: MOREIRA Liam | D27: U11 | E27: 1 | F27: 1 | G27: 0 | H27: 0 | I27: 0 | J27: 0 | M27: 0 | N27: 0 | O27: 0 | P27: 0 | Q27: 0 | R27: 0 | S27: 0 | V27: 0 | W27: 0 | X27: 0 | Y27: 1 | Z27: 0 | AA27: 0 | AB27: 1 | AE27: 1 | AF27: 0 | AG27: 0 | AU27: =SUM(I27:AT27) -> 3
B28: 2 | C28: DEVOS Adam | D28: U11 | E28: 1 | F28: 1 | G28: 1 | H28: 1 | I28: 1 | J28: 1 | M28: 1 | N28: 1 | O28: 1 | P28: 1 | Q28: 1 | R28: 1 | S28: 1 | V28: 1 | W28: 0 | X28: 1 | Y28: 1 | Z28: 1 | AA28: 0 | AB28: 1 | AE28: 1 | AF28: 1 | AG28: 1 | AU28: =SUM(I28:AT28) -> 17
B29: 3 | C29: MOLINA NEGRE Ruben | D29: U11 | E29: 1 | F29: 1 | G29: 1 | H29: 0 | I29: 0 | J29: 0 | M29: 1 | N29: 1 | O29: 1 | P29: 1 | Q29: 1 | R29: 1 | S29: 1 | V29: 0 | W29: 1 | X29: 1 | Y29: 1 | Z29: 0 | AA29: 1 | AB29: 1 | AE29: 1 | AF29: 1 | AG29: 1 | AU29: =SUM(I29:AT29) -> 15
B30: 4 | C30: MOUMEN Maher | D30: U11 | E30: 1 | F30: 1 | G30: 1 | H30: 1 | I30: 1 | J30: 1 | M30: 1 | N30: 1 | O30: 1 | P30: 1 | Q30: 1 | R30: 1 | S30: 1 | V30: 1 | W30: 1 | X30: 1 | Y30: 1 | Z30: 1 | AA30: 1 | AB30: 1 | AE30: 1 | AF30: 1 | AG30: 1 | AU30: =SUM(I30:AT30) -> 19
B31: 5 | C31: MOUMEN Wael | D31: U11 | E31: 1 | F31: 1 | G31: 1 | H31: 1 | I31: 1 | J31: 1 | M31: 1 | N31: 1 | O31: 1 | P31: 1 | Q31: 1 | R31: 1 | S31: 1 | V31: 1 | W31: 1 | X31: 1 | Y31: 1 | Z31: 1 | AA31: 1 | AB31: 1 | AE31: 1 | AF31: 1 | AG31: 1 | AU31: =SUM(I31:AT31) -> 19
B32: 6 | C32: BEAUMONT Elie | D32: U11 | E32: 0 | F32: 1 | G32: 1 | H32: 0 | I32: 1 | J32: 1 | M32: 1 | N32: 1 | O32: 1 | P32: 1 | Q32: 1 | R32: 1 | S32: 1 | V32: 1 | W32: 1 | X32: 1 | Y32: 1 | Z32: 1 | AA32: 1 | AB32: 1 | AE32: 1 | AF32: 1 | AG32: Bagare | AU32: =SUM(I32:AT32) -> 18
B33: 7 | C33: GOMIS Noam | D33: U11 | E33: 0 | F33: 0 | G33: 0 | H33: 0 | I33: 0 | J33: 1 | M33: 1 | N33: 1 | O33: 1 | P33: 1 | Q33: 1 | R33: 1 | S33: 1 | V33: 1 | W33: 1 | X33: 1 | Y33: 1 | Z33: 1 | AA33: 1 | AB33: 1 | AE33: 1 | AF33: 0 | AG33: 0 | AU33: =SUM(I33:AT33) -> 16
B34: 8 | C34: BAMBA Karim Christ Emmanuel | D34: U12 | E34: 1 | F34: 1 | G34: 1 | H34: 1 | I34: 0 | J34: 1 | M34: 1 | N34: 0 | O34: 0 | P34: 1 | Q34: 1 | R34: 1 | S34: 1 | V34: 0 | W34: 1 | X34: 1 | Y34: 1 | Z34: 1 | AA34: 1 | AB34: 0 | AE34: 1 | AF34: 0 | AG34: 1 | AU34: =SUM(I34:AT34) -> 13
B35: 9 | C35: ARBONA Florian | D35: U12 | E35: 1 | F35: 1 | G35: 1 | H35: 1 | I35: 1 | J35: 1 | M35: 1 | N35: 1 | O35: 1 | P35: 1 | Q35: 1 | R35: 1 | S35: 1 | V35: 1 | W35: 0 | X35: 0 | Y35: 1 | Z35: 1 | AA35: 1 | AB35: 0 | AE35: 1 | AF35: 1 | AG35: 1 | AU35: =SUM(I35:AT35) -> 16
B36: 10 | C36: MAGOSSOU Melphy Antoine | D36: U12 | E36: 1 | F36: 1 | G36: 1 | H36: 1 | I36: 1 | J36: 1 | M36: 1 | N36: 1 | O36: 1 | P36: 1 | Q36: 0 | R36: 1 | S36: 1 | V36: 0 | W36: 1 | X36: 0 | Y36: 0 | Z36: 0 | AA36: 0 | AB36: 1 | AE36: 1 | AF36: 0 | AG36: 0 | AU36: =SUM(I36:AT36) -> 11
B37: 11 | C37: ABOU LEYA Adam | D37: U12 | E37: 1 | F37: 1 | G37: 1 | H37: 1 | I37: 1 | J37: 1 | M37: 1 | N37: 1 | O37: 1 | P37: 1 | Q37: 1 | R37: 1 | S37: 1 | V37: 0 | W37: 1 | X37: 1 | Y37: 1 | Z37: 1 | AA37: 1 | AB37: 0 | AE37: 1 | AF37: 0 | AG37: 1 | AU37: =SUM(I37:AT37) -> 16
B38: 12 | C38: MARTIN CHOPINAUD Louis | D38: U12 | E38: 1 | F38: 1 | G38: 1 | H38: 1 | I38: 1 | J38: 1 | M38: 1 | N38: 1 | O38: 1 | P38: 1 | Q38: 1 | R38: 0 | S38: 1 | V38: 0 | W38: 0 | X38: 1 | Y38: 1 | Z38: 1 | AA38: 1 | AB38: 1 | AE38: 1 | AF38: 1 | AG38: 1 | AU38: =SUM(I38:AT38) -> 16
B39: 13 | C39: MOREIRA Lucas | D39: U12 | E39: 1 | F39: 1 | G39: 1 | H39: 1 | I39: 1 | J39: 1 | M39: 1 | N39: 1 | O39: 1 | P39: 1 | Q39: 1 | R39: 1 | S39: 1 | V39: 1 | W39: 1 | X39: 1 | Y39: 1 | Z39: 1 | AA39: 1 | AB39: 1 | AE39: 1 | AF39: 1 | AG39: 1 | AU39: =SUM(I39:AT39) -> 19
B40: 14 | C40: GUERRERO Nino | D40: U12 | E40: 1 | F40: 1 | G40: 1 | H40: 1 | I40: 1 | J40: 1 | M40: 1 | N40: 1 | O40: 1 | P40: 1 | Q40: 1 | R40: 1 | S40: 1 | V40: 0 | W40: 1 | X40: 1 | Y40: 0 | Z40: 1 | AA40: 1 | AB40: 1 | AE40: 1 | AF40: 1 | AG40: 1 | AU40: =SUM(I40:AT40) -> 17
B41: 15 | C41: GONCALVES Gabin | D41: U12 | E41: 1 | F41: 1 | G41: 1 | H41: 1 | I41: 1 | J41: 1 | M41: 1 | N41: 1 | O41: 1 | P41: 1 | Q41: 0 | R41: 1 | S41: 1 | V41: 0 | W41: 1 | X41: 1 | Y41: 1 | Z41: 0 | AA41: 1 | AB41: 1 | AE41: 1 | AF41: 1 | AG41: 1 | AU41: =SUM(I41:AT41) -> 16
B42: 16 | C42: GARBAA Ilyas | D42: U12 | E42: 1 | F42: 1 | G42: 1 | H42: 1 | I42: 1 | J42: 1 | M42: 1 | N42: 1 | O42: 1 | P42: 1 | Q42: 1 | R42: 1 | S42: 1 | V42: 1 | W42: 1 | X42: 1 | Y42: 1 | Z42: 1 | AA42: 1 | AB42: 0 | AE42: 1 | AF42: 0 | AG42: Bagare | AU42: =SUM(I42:AT42) -> 16
B43: 16 | C43: TOTAL G2 | E43: =COUNTIF(E27:E42,"1") -> 14 | F43: =COUNTIF(F27:F42,"1") -> 15 | G43: =COUNTIF(G27:G42,"1") -> 14 | H43: =COUNTIF(H27:H42,"1") -> 12 | I43: =COUNTIF(I27:I42,"1") -> 12 | J43: =COUNTIF(J27:J42,"1") -> 14 | K43: =COUNTIF(K27:K42,"1") -> 0 | L43: =COUNTIF(L27:L42,"1") -> 0 | ... AT43: =COUNTIF(AT27:AT42,"1") -> 0 | AU43: =SUM(I43:AT43) -> 247
E44: 45910 | F44: =E44+7 -> 45917 | G44: =F44+7 -> 45924 | H44: =G44+7 -> 45931 | I44: =H44+7 -> 45938 | J44: =I44+7 -> 45945 | K44: =J44+7 -> 45952 | L44: =K44+7 -> 45959 | M44: =L44+7 -> 45966 | ... AT44: =AS44+7 -> 46197
E46: S1 | F46: S2 | G46: S3 | H46: S4 | I46: S5 | J46: S6 | K46: V | L46: V | M46: S7 | N46: S8 | O46: S9 | P46: S10 | Q46: S11 | R46: S12 | S46: S13 | T46: V | U46: V | V46: S14 | W46: S15 | X46: S16 | Y46: S17 | Z46: S18 | AA46: S19 | AB46: S20 | AC46: V | AD46: V | AE46: S21 | AF46: S22 | AG46: S23 | AH46: S24 | AI46: S25 | AJ46: S26 | AK46: V | AL46: V | AM46: S27 | AN46: S28 | AO46: F | AP46: S29 | AQ46: S30 | AR46: S31 | AS46: S32 | AT46: S33 | AU46: =SUM(I46:AT46) -> 0
...

Sheet VENDREDI 17h30 Présence
C1: VENDREDI 17H30
E4: 45912 | F4: =E4+7 -> 45919 | G4: =F4+7 -> 45926 | H4: =G4+7 -> 45933 | I4: =H4+7 -> 45940 | J4: =I4+7 -> 45947 | K4: =J4+7 -> 45954 | L4: =K4+7 -> 45961 | M4: =L4+7 -> 45968 | ... AT4: =AS4+7 -> 46199
C5: ='BABY Présence'!C4 -> MAJ LISTE 11/03 : 12h15
A6: 1er groupe | C6: TOTAL INSCRIPTION EDF : | D6: ='BABY Présence'!D5 -> 321 | E6: S1 | F6: S2 | G6: S3 | H6: S4 | I6: S5 | J6: S6 | K6: V | L6: V | M6: S7 | N6: S8 | O6: S9 | P6: S10 | Q6: S11 | R6: S12 | S6: S13 | T6: V | U6: V | V6: S14 | W6: S15 | X6: S16 | Y6: S17 | Z6: S18 | AA6: S19 | AB6: S20 | AC6: V | AD6: V | AE6: S21 | AF6: S22 | AG6: S23 | AH6: S24 | AI6: S25 | AJ6: S26 | AK6: V | AL6: V | AM6: S27 | AN6: S28 | AO6: F | AP6: S29 | AQ6: S30 | AR6: S31 | AS6: S32 | AT6: S33
B7: 1 | C7: TRIN Léo | D7: U6 | E7: 0 | F7: 1 | G7: 1 | H7: 0 | I7: 1 | J7: 1 | M7: 0 | N7: 1 | O7: 1 | P7: 1 | Q7: 1 | R7: 1 | S7: 0 | V7: 1 | W7: 1 | X7: 1 | Y7: 1 | Z7: 1 | AA7: 1 | AB7: 0 | AD7: 1 | AE7: 1 | AF7: 1 | AG7: 1 | AU7: =SUM(I7:AT7) -> 17
B8: 2 | C8: PEGUET Edgar | D8: U6 | E8: 1 | F8: 0 | G8: 1 | H8: 1 | I8: 1 | J8: 1 | M8: 1 | N8: 0 | O8: 1 | P8: 1 | Q8: 1 | R8: 1 | S8: 1 | V8: 1 | W8: 1 | X8: 1 | Y8: 1 | Z8: 1 | AA8: 1 | AB8: 1 | AD8: 1 | AE8: 1 | AF8: 1 | AG8: 1 | AU8: =SUM(I8:AT8) -> 19
B9: 3 | C9: AL HASSAN Yousef | D9: U6 | E9: 1 | F9: 1 | G9: 0 | H9: 1 | I9: 0 | J9: 1 | M9: 1 | N9: 1 | O9: 0 | P9: 1 | Q9: 1 | R9: 1 | S9: 1 | V9: 1 | W9: 1 | X9: 1 | Y9: 1 | Z9: 0 | AA9: 1 | AB9: 0 | AD9: 0 | AE9: 0 | AF9: 0 | AG9: 0 | AU9: =SUM(I9:AT9) -> 12
B10: 4 | C10: SIMON Gabriel | D10: U6 | E10: 1 | F10: 1 | G10: 1 | H10: 1 | I10: 1 | J10: 1 | M10: 1 | N10: 0 | O10: 1 | P10: 1 | Q10: 1 | R10: 0 | S10: 0 | V10: 0 | W10: 0 | X10: 1 | Y10: 1 | Z10: 1 | AA10: 0 | AB10: 1 | AD10: 0 | AE10: 1 | AF10: 1 | AG10: 1 | AU10: =SUM(I10:AT10) -> 13
B11: 5 | C11: SAFA Jad | D11: U6 | E11: 1 | F11: 1 | G11: 1 | H11: 1 | I11: 1 | J11: 1 | M11: 0 | N11: 1 | O11: 1 | P11: 1 | Q11: 1 | R11: 1 | S11: 1 | V11: 1 | W11: 1 | X11: 1 | Y11: 1 | Z11: 1 | AA11: 1 | AB11: 1 | AD11: 1 | AE11: 1 | AF11: 1 | AG11: 1 | AU11: =SUM(I11:AT11) -> 19
B12: 6 | C12: GRIMAL Johan | D12: U7 | E12: 1 | F12: 1 | G12: 1 | H12: 1 | I12: 1 | J12: 1 | M12: 1 | N12: 1 | O12: 1 | P12: 1 | Q12: 1 | R12: 1 | S12: 1 | V12: 1 | W12: 1 | X12: 1 | Y12: 1 | Z12: 1 | AA12: 1 | AB12: 1 | AD12: 1 | AE12: 1 | AF12: 0 | AG12: 1 | AU12: =SUM(I12:AT12) -> 19
B13: 7 | C13: TEIXEIRA RICHARD Paul | D13: U7 | E13: 1 | F13: 1 | G13: 1 | H13: 1 | I13: 1 | J13: 1 | M13: 1 | N13: 1 | O13: 1 | P13: 1 | Q13: 1 | R13: 1 | S13: 0 | V13: 0 | W13: 1 | X13: 0 | Y13: 1 | Z13: 1 | AA13: 0 | AB13: 1 | AD13: 0 | AE13: 1 | AF13: 0 | AG13: 1 | AU13: =SUM(I13:AT13) -> 14
B14: 8 | C14: BEN ABDELJELIL Zakarya | D14: U7 | E14: 1 | F14: 1 | G14: 1 | H14: 1 | I14: 1 | J14: 1 | M14: 1 | N14: 0 | O14: 1 | P14: 0 | Q14: 0 | R14: 1 | S14: 0 | V14: 1 | W14: 1 | X14: 1 | Y14: 1 | Z14: 1 | AA14: 1 | AB14: 1 | AD14: 1 | AE14: 1 | AF14: 1 | AG14: 1 | AU14: =SUM(I14:AT14) -> 16
B15: 9 | C15: SUN Jimmy | D15: U7 | E15: 1 | F15: 1 | G15: 0 | H15: 1 | I15: 1 | J15: 0 | M15: 1 | N15: 1 | O15: 1 | P15: 1 | Q15: 1 | R15: 1 | S15: 1 | V15: 1 | W15: 1 | X15: 1 | Y15: 0 | Z15: 1 | AA15: 0 | AB15: 1 | AE15: 1 | AF15: 1 | AG15: 1 | AU15: =SUM(I15:AT15) -> 16
B16: 10 | C16: ELKHALFIOUI Wakil | D16: U7 | E16: 0 | F16: 0 | G16: 0 | H16: 0 | I16: 0 | J16: 1 | M16: 1 | N16: 1 | O16: 1 | P16: 1 | Q16: 1 | R16: 0 | S16: 0 | V16: 1 | W16: 1 | X16: 0 | Y16: 1 | Z16: 1 | AA16: 1 | AB16: 0 | AE16: 1 | AF16: 0 | AG16: 0 | AU16: =SUM(I16:AT16) -> 12
B17: 11 | C17: MURILLO-NNABUIHE Caymmi | D17: U8 | E17: 1 | F17: 1 | G17: 1 | H17: 1 | I17: 0 | J17: 0 | M17: 1 | N17: 0 | O17: 0 | P17: 0 | Q17: 1 | R17: 0 | S17: 0 | V17: 0 | W17: 1 | X17: 1 | Y17: 0 | Z17: 0 | AA17: 0 | AB17: 1 | AE17: 1 | AF17: 1 | AG17: 1 | AU17: =SUM(I17:AT17) -> 8
B18: 12 | C18: HARZALLAH Zakaria | D18: U8 | E18: 0 | F18: 1 | G18: 1 | H18: 0 | I18: 1 | J18: 1 | M18: 1 | N18: 1 | O18: 1 | P18: 1 | Q18: 1 | R18: 1 | S18: 1 | V18: 1 | W18: 0 | X18: 1 | Y18: 1 | Z18: 1 | AA18: 1 | AB18: 1 | AE18: 1 | AF18: 1 | AG18: 1 | AU18: =SUM(I18:AT18) -> 18
B19: 13 | C19: LEMOINE Anatole | D19: U8 | E19: 1 | F19: 1 | G19: 1 | H19: 1 | I19: 1 | J19: 0 | M19: 1 | N19: 1 | O19: 0 | P19: 0 | Q19: 1 | R19: 0 | S19: 0 | V19: 1 | W19: 1 | X19: 0 | Y19: 1 | Z19: 1 | AA19: 1 | AB19: 0 | AE19: 1 | AF19: 1 | AG19: 0 | AU19: =SUM(I19:AT19) -> 11
B20: 14 | C20: PETITJEAN Maxance | D20: U8 | E20: 1 | F20: 0 | G20: 0 | H20: 0 | I20: 0 | J20: 0 | M20: 1 | N20: 1 | O20: 1 | P20: 1 | Q20: 1 | R20: 1 | S20: 1 | V20: 1 | W20: 1 | X20: MAL | Y20: 1 | Z20: 1 | AA20: 1 | AB20: 0 | AE20: 1 | AF20: 1 | AG20: 0 | AU20: =SUM(I20:AT20) -> 14
B21: 15 | C21: GASPARINI CASTRO Matteo | D21: U7 | E21: 0 | F21: 0 | G21: 0 | H21: 0 | I21: 0 | J21: 0 | M21: 0 | N21: 0 | O21: 0 | P21: 0 | Q21: 0 | R21: 0 | S21: 0 | V21: 1 | W21: 1 | X21: 1 | Y21: 1 | Z21: 1 | AA21: 1 | AB21: 0 | AE21: 1 | AF21: 1 | AG21: 1 | AU21: =SUM(I21:AT21) -> 9
B22: 16 | C22: LARBAOUI El Mehdi | D22: U6 | E22: 0 | F22: 0 | G22: 0 | H22: 0 | I22: 0 | J22: 0 | M22: 0 | N22: 0 | O22: 0 | P22: 0 | Q22: 0 | R22: 0 | S22: 0 | V22: 0 | W22: 0 | X22: 1 | Y22: 1 | Z22: 1 | AA22: 1 | AB22: 0 | AE22: 0 | AF22: 0 | AG22: 1 | AU22: =SUM(I22:AT22) -> 5
B23: 16 | C23: TOTAL G1 | E23: =COUNTIF(E7:E22,"1") -> 11 | F23: =COUNTIF(F7:F22,"1") -> 11 | G23: =COUNTIF(G7:G22,"1") -> 10 | H23: =COUNTIF(H7:H22,"1") -> 10 | I23: =COUNTIF(I7:I22,"1") -> 10 | J23: =COUNTIF(J7:J22,"1") -> 10 | K23: =COUNTIF(K7:K22,"1") -> 0 | L23: =COUNTIF(L7:L22,"1") -> 0 | ... AT23: =COUNTIF(AT7:AT22,"1") -> 0 | AU23: =SUM(I23:AT23) -> 222
E24: 45912 | F24: =E24+7 -> 45919 | G24: =F24+7 -> 45926 | H24: =G24+7 -> 45933 | I24: =H24+7 -> 45940 | J24: =I24+7 -> 45947 | K24: =J24+7 -> 45954 | L24: =K24+7 -> 45961 | M24: =L24+7 -> 45968 | ... AT24: =AS24+7 -> 46199
E26: S1 | F26: S2 | G26: S3 | H26: S4 | I26: S5 | J26: S6 | K26: V | L26: V | M26: S7 | N26: S8 | O26: S9 | P26: S10 | Q26: S11 | R26: S12 | S26: S13 | T26: V | U26: V | V26: S14 | W26: S15 | X26: S16 | Y26: S17 | Z26: S18 | AA26: S19 | AB26: S20 | AC26: V | AD26: V | AE26: S21 | AF26: S22 | AG26: S23 | AH26: S24 | AI26: S25 | AJ26: S26 | AK26: V | AL26: V | AM26: S27 | AN26: S28 | AO26: F | AP26: S29 | AQ26: S30 | AR26: S31 | AS26: S32 | AT26: S33
A27: 2è groupe | B27: 1 | C27: ZORGATI Ryan | D27: U8 | E27: 1 | F27: 1 | G27: 1 | H27: 1 | I27: 1 | J27: 1 | M27: 1 | N27: 1 | O27: 1 | P27: 1 | Q27: 1 | R27: 1 | S27: 1 | V27: 1 | W27: 1 | X27: 0 | Z27: 1 | AA27: 1 | AB27: 1 | AE27: 1 | AF27: 1 | AG27: 1 | AU27: =SUM(I27:AT27) -> 17
B28: 2 | C28: BRADAI Adam | D28: U8 | E28: 0 | F28: 1 | G28: 1 | H28: 1 | I28: 1 | J28: 0 | M28: 1 | N28: 1 | O28: 1 | P28: 1 | Q28: 1 | R28: 0 | S28: 1 | V28: 1 | W28: 1 | X28: 1 | Y28: 1 | Z28: 1 | AA28: 1 | AB28: 1 | AE28: 1 | AF28: 1 | AG28: 1 | AU28: =SUM(I28:AT28) -> 17
B29: 3 | C29: ALADWAN Shahim | D29: U9 | E29: 1 | F29: 1 | G29: 1 | H29: 1 | I29: 1 | J29: 1 | M29: 1 | N29: 1 | O29: 1 | P29: 1 | Q29: 1 | R29: 1 | S29: 1 | V29: 1 | W29: 1 | X29: 1 | Y29: 1 | Z29: 1 | AA29: 1 | AB29: 1 | AE29: 1 | AF29: 1 | AG29: 1 | AU29: =SUM(I29:AT29) -> 19
B30: 4 | C30: KATAOKA Ren | D30: U9 | E30: 0 | F30: 1 | G30: 0 | H30: 0 | I30: 1 | J30: 1 | M30: 0 | N30: 1 | O30: 1 | P30: 0 | Q30: 0 | R30: 1 | S30: 1 | V30: 1 | W30: 1 | X30: 0 | Y30: 1 | Z30: 1 | AA30: 1 | AB30: 1 | AE30: 1 | AF30: 1 | AG30: 1 | AU30: =SUM(I30:AT30) -> 15
B31: 5 | C31: BEN ABDELJELIL Skander | D31: U9 | E31: 1 | F31: 1 | G31: 1 | H31: 1 | I31: 1 | J31: 1 | M31: 0 | N31: 1 | O31: 1 | P31: 1 | Q31: 1 | R31: 1 | S31: 1 | V31: 1 | W31: 1 | X31: 1 | Y31: 1 | Z31: 1 | AA31: 1 | AB31: 1 | AE31: 1 | AF31: 1 | AG31: 1 | AU31: =SUM(I31:AT31) -> 18
B32: 6 | C32: SEMPE Soan | D32: U9 | E32: 1 | F32: 1 | G32: 1 | H32: 1 | I32: 1 | J32: 1 | M32: 1 | N32: 1 | O32: 1 | P32: 1 | Q32: 1 | R32: 1 | S32: 1 | V32: 0 | W32: 1 | X32: 1 | Z32: 1 | AA32: 0 | AB32: 1 | AE32: 1 | AF32: 1 | AG32: 1 | AU32: =SUM(I32:AT32) -> 16
B33: 7 | C33: KHASAEEBAH Adim | D33: U10 | E33: 0 | F33: 0 | G33: 0 | H33: 0 | I33: 0 | J33: 0 | M33: 1 | N33: 1 | O33: 1 | P33: 1 | Q33: 1 | R33: 1 | S33: 1 | V33: 1 | W33: 0 | X33: 1 | Y33: 1 | Z33: 1 | AA33: 0 | AB33: 1 | AE33: 0 | AF33: 0 | AG33: 1 | AU33: =SUM(I33:AT33) -> 13
B34: 8 | C34: PEGUET Achille | D34: U10 | E34: 1 | F34: 1 | G34: 1 | H34: 1 | I34: 1 | J34: 1 | M34: 1 | N34: 1 | O34: 1 | P34: 1 | Q34: 1 | R34: 1 | S34: 1 | V34: 1 | W34: 1 | X34: 1 | Y34: 1 | Z34: 1 | AA34: 1 | AB34: 1 | AE34: 1 | AF34: 1 | AG34: 1 | AU34: =SUM(I34:AT34) -> 19
B35: 9 | C35: GRIMAL Adria | D35: U10 | E35: 1 | F35: 1 | G35: 1 | H35: 1 | I35: 0 | J35: 1 | M35: 1 | N35: 1 | O35: 0 | P35: 0 | Q35: 1 | R35: 0 | S35: 0 | V35: 0 | W35: 1 | X35: 1 | Z35: 1 | AA35: 1 | AB35: 1 | AE35: 1 | AF35: 0 | AG35: 1 | AU35: =SUM(I35:AT35) -> 11
B36: 10 | C36: AMADIEU BALAVOINE Basile | D36: U10 | E36: 1 | F36: 1 | G36: 1 | H36: 1 | I36: 1 | J36: 1 | M36: 1 | N36: 1 | O36: 1 | P36: 0 | Q36: 1 | R36: 1 | S36: 1 | V36: 1 | W36: 1 | X36: 1 | Y36: 1 | Z36: 1 | AA36: 1 | AB36: 1 | AE36: 1 | AF36: 1 | AG36: 1 | AU36: =SUM(I36:AT36) -> 18
B37: 11 | C37: REGIS Noé | D37: U10 | E37: 1 | F37: 1 | G37: 1 | H37: 1 | I37: 1 | J37: 1 | M37: 1 | N37: 1 | O37: 1 | P37: 0 | Q37: 1 | R37: 0 | S37: 0 | V37: 1 | W37: 1 | X37: 0 | Y37: 1 | Z37: 1 | AA37: 1 | AB37: 1 | AE37: 1 | AF37: 1 | AU37: =SUM(I37:AT37) -> 14
B38: 12 | C38: NICOLLE Noah | D38: U10 | E38: 0 | F38: 0 | G38: 0 | H38: 1 | I38: 1 | J38: 1 | M38: 1 | N38: 1 | O38: 1 | P38: 1 | Q38: 1 | R38: 1 | S38: 1 | V38: 1 | W38: 0 | X38: 0 | Y38: 1 | Z38: 1 | AA38: 1 | AB38: 1 | AE38: 1 | AF38: 1 | AG38: 1 | AU38: =SUM(I38:AT38) -> 17
B39: 13 | C39: AL HASSAN Karam | D39: U11 | E39: 0 | F39: 1 | G39: 1 | H39: 0 | I39: 1 | J39: 1 | M39: 1 | N39: 1 | O39: 0 | P39: 0 | Q39: 1 | R39: 0 | S39: 1 | V39: 0 | W39: 1 | X39: 1 | Z39: 1 | AA39: 1 | AB39: 1 | AE39: 1 | AF39: 1 | AG39: 1 | AU39: =SUM(I39:AT39) -> 14
B40: 14 | C40: BELFQUIH Amine | D40: U12 | E40: 0 | F40: 1 | G40: 0 | H40: 0 | I40: 0 | J40: 0 | M40: 0 | N40: 0 | O40: 1 | P40: 0 | Q40: 1 | R40: 0 | S40: 1 | V40: 0 | W40: 0 | X40: 1 | Z40: 1 | AA40: 1 | AB40: 1 | AE40: 1 | AF40: 0 | AU40: =SUM(I40:AT40) -> 8
B41: 15 | C41: ARIF Adam | D41: U10 | E41: 0 | F41: 0 | G41: 0 | H41: 0 | I41: 0 | J41: 0 | M41: 0 | N41: 0 | O41: 1 | P41: 1 | Q41: 1 | R41: 1 | S41: 0 | V41: 0 | W41: 1 | X41: 1 | Y41: 1 | Z41: 1 | AA41: 1 | AB41: 1 | AE41: 1 | AF41: 0 | AG41: 1 | AU41: =SUM(I41:AT41) -> 12
B42: 15 | C42: TOTAL G2 | E42: =COUNTIF(E27:E41,"1") -> 8 | F42: =COUNTIF(F27:F41,"1") -> 12 | G42: =COUNTIF(G27:G41,"1") -> 10 | H42: =COUNTIF(H27:H41,"1") -> 10 | I42: =COUNTIF(I27:I41,"1") -> 11 | J42: =COUNTIF(J27:J41,"1") -> 11 | K42: =COUNTIF(K27:K41,"1") -> 0 | L42: =COUNTIF(L27:L41,"1") -> 0 | ... AT42: =COUNTIF(AT27:AT41,"1") -> 0 | AU42: =SUM(I42:AT42) -> 228
E43: 45912 | F43: =E43+7 -> 45919 | G43: =F43+7 -> 45926 | H43: =G43+7 -> 45933 | I43: =H43+7 -> 45940 | J43: =I43+7 -> 45947 | K43: =J43+7 -> 45954 | L43: =K43+7 -> 45961 | M43: =L43+7 -> 45968 | ... AT43: =AS43+7 -> 46199
...

Sheet SAMEDI 9h30 Présence
C1: SAMEDI 09H30
E4: 45913 | F4: =E4+7 -> 45920 | G4: =F4+7 -> 45927 | H4: =G4+7 -> 45934 | I4: =H4+7 -> 45941 | J4: =I4+7 -> 45948 | K4: =J4+7 -> 45955 | L4: =K4+7 -> 45962 | M4: =L4+7 -> 45969 | ... AT4: =AS4+7 -> 46200
C5: ='BABY Présence'!C4 -> MAJ LISTE 11/03 : 12h15
A6: 1er groupe | C6: TOTAL INSCRIPTION EDF : | D6: ='BABY Présence'!D5 -> 321 | E6: S1 | F6: S2 | G6: S3 | H6: S4 | I6: S5 | J6: S6 | K6: V | L6: V | M6: S7 | N6: S8 | O6: S9 | P6: S10 | Q6: S11 | R6: S12 | S6: S13 | T6: V | U6: V | V6: S14 | W6: S15 | X6: S16 | Y6: S17 | Z6: S18 | AA6: S19 | AB6: S20 | AC6: V | AD6: V | AE6: S21 | AF6: S22 | AG6: S23 | AH6: S24 | AI6: S25 | AJ6: S26 | AK6: V | AL6: V | AM6: S27 | AN6: S28 | AO6: F | AP6: S29 | AQ6: S30 | AR6: S31 | AS6: S32 | AT6: S33 | AU6: =SUM(I6:AT6) -> 0
B7: 1 | C7: ABOU LEYLA Ilyes | D7: U6 | E7: 1 | F7: 1 | G7: 1 | H7: 1 | I7: 0 | M7: 1 | N7: 1 | O7: 0 | P7: 0 | Q7: 1 | R7: 1 | V7: 1 | W7: 1 | X7: 1 | Y7: 1 | Z7: 1 | AA7: 1 | AB7: 0 | AD7: 1 | AE7: 0 | AF7: 1 | AG7: 0 | AU7: =SUM(I7:AT7) -> 12
B8: 2 | C8: CALSAT Raphaël | D8: U6 | E8: 1 | F8: 1 | G8: 1 | H8: 1 | I8: 0 | M8: 1 | N8: 1 | O8: 1 | P8: 0 | Q8: 1 | R8: 1 | V8: 1 | W8: 1 | X8: 1 | Y8: 1 | Z8: 1 | AA8: 1 | AB8: 0 | AD8: 1 | AE8: 1 | AF8: 1 | AU8: =SUM(I8:AT8) -> 14
B9: 3 | C9: FONTAINE Erez | D9: U6 | E9: 1 | F9: 1 | G9: 1 | H9: 0 | I9: 1 | M9: 0 | N9: 0 | O9: 1 | P9: 1 | Q9: 1 | R9: 1 | V9: 1 | W9: 0 | X9: 1 | Y9: 0 | Z9: 1 | AA9: 1 | AB9: 1 | AD9: 1 | AE9: 1 | AF9: 0 | AU9: =SUM(I9:AT9) -> 12
B10: 4 | C10: ANDRE Salomon | D10: U6 | E10: 1 | F10: 1 | G10: 1 | H10: 1 | I10: 0 | M10: 1 | N10: 1 | O10: 1 | P10: 1 | Q10: 1 | R10: 1 | V10: 1 | W10: 1 | X10: 1 | Y10: 1 | Z10: 1 | AA10: 0 | AB10: 0 | AD10: 1 | AE10: 1 | AF10: 0 | AU10: =SUM(I10:AT10) -> 13
B11: 5 | C11: DHAKAR Zayd | D11: U6 | E11: 1 | F11: 1 | G11: 1 | H11: 1 | I11: 1 | M11: 1 | N11: 1 | O11: 1 | P11: 1 | Q11: 1 | R11: 0 | V11: 0 | W11: 1 | X11: 1 | Y11: 1 | Z11: 1 | AA11: 1 | AB11: 1 | AD11: 0 | AE11: 1 | AF11: 1 | AU11: =SUM(I11:AT11) -> 14
B12: 6 | C12: GUENNECPINTOR Isaac | D12: U6 | E12: 1 | F12: 1 | G12: 1 | H12: 0 | I12: 1 | M12: 1 | N12: 1 | O12: 0 | P12: 1 | Q12: 0 | R12: 1 | V12: 1 | W12: 1 | X12: 1 | Y12: 1 | Z12: 1 | AA12: 1 | AB12: 1 | AD12: 1 | AE12: 1 | AF12: 1 | AU12: =SUM(I12:AT12) -> 15
B13: 7 | C13: MHIRA Yassir | D13: U6 | E13: 1 | F13: 1 | G13: 0 | H13: 1 | I13: 1 | M13: 1 | N13: 1 | O13: 0 | P13: 1 | Q13: 1 | R13: 0 | V13: 0 | W13: 1 | X13: 1 | Y13: 1 | Z13: 1 | AA13: 1 | AB13: 1 | AD13: 1 | AE13: 1 | AF13: 1 | AU13: =SUM(I13:AT13) -> 14
B14: 8 | C14: MARTIN Lonni | D14: U6 | E14: 1 | F14: 0 | G14: 1 | H14: 0 | I14: 1 | M14: 1 | N14: 1 | O14: 1 | P14: 1 | Q14: 1 | R14: 1 | V14: 1 | W14: 1 | X14: 1 | Y14: 1 | Z14: 0 | AA14: 1 | AB14: 1 | AD14: 1 | AE14: 1 | AF14: 0 | AU14: =SUM(I14:AT14) -> 15
B15: 9 | C15: BEN MAHMOUD Aylan | D15: U6 | E15: 0 | F15: 1 | G15: 0 | H15: 0 | I15: 1 | M15: 1 | N15: 1 | O15: 1 | P15: 0 | Q15: 0 | R15: 0 | V15: 1 | W15: 1 | X15: 1 | Y15: 0 | Z15: 1 | AA15: 1 | AB15: 1 | AD15: 1 | AE15: 0 | AF15: 1 | AU15: =SUM(I15:AT15) -> 12
B16: 10 | C16: FONTAINE Aaron | D16: U7 | E16: 1 | F16: 1 | G16: 1 | H16: 1 | I16: 1 | M16: 1 | N16: 1 | O16: 1 | W16: 1 | X16: 1 | Y16: 1 | Z16: 0 | AA16: 1 | AB16: 1 | AE16: 1 | AF16: 0 | AU16: =SUM(I16:AT16) -> 10
B17: 11 | C17: FONTAINE Erwan | D17: U7 | E17: 1 | F17: 0 | G17: 1 | H17: 1 | I17: 1 | M17: 1 | N17: 1 | O17: 1 | W17: 0 | X17: 1 | Y17: 1 | Z17: 0 | AA17: 1 | AB17: 1 | AE17: 1 | AF17: 1 | AU17: =SUM(I17:AT17) -> 10
B18: 12 | C18: VIALETTE Eden | D18: U7 | E18: 1 | F18: 1 | G18: 1 | H18: 1 | I18: 1 | M18: 0 | O18: 1 | W18: 0 | X18: 1 | Y18: 0 | Z18: 1 | AA18: 0 | AB18: 0 | AE18: 0 | AF18: 0 | AU18: =SUM(I18:AT18) -> 4
B19: 13 | C19: ANTIC MOREAU Jules | D19: U7 | E19: 1 | F19: 1 | G19: 1 | H19: 0 | I19: 1 | M19: 1 | N19: 1 | O19: 1 | W19: 1 | X19: 1 | Y19: 1 | Z19: 1 | AA19: 1 | AB19: 0 | AE19: 1 | AF19: 1 | AU19: =SUM(I19:AT19) -> 11
B20: 14 | C20: AHITOUR Younes | D20: U7 | E20: 1 | F20: 1 | G20: 1 | H20: 1 | I20: 1 | M20: 1 | N20: 1 | O20: 1 | W20: 1 | X20: 0 | Y20: 1 | Z20: 1 | AA20: 1 | AB20: 1 | AE20: 1 | AF20: 0 | AU20: =SUM(I20:AT20) -> 10
